8=FIX.4.4|9=2760|35=W|49=LFX|56=MKT.UAT.QPU600|34=2|52=20190307-15:20:20.046|262=MDReqID_1|55=GBP/USD|64=20190311|268=20|269=0|280=2BNP51|278=b-47005812040140660-1|270=1.31017|271=5000000|272=20190307|273=15:20:15.603|9122=15:20:15.601|15=GBP|276=A|269=0|280=1GBP/USD.1M@BAR.7.RFQ|278=b-47005812040140660-2|270=1.31016|271=1000000|272=20190307|273=15:20:16.101|9122=15:20:16.076|15=GBP|276=A|110=0|269=0|280=2BNP52|278=b-47005812040140660-3|270=1.31014|271=6000000|272=20190307|273=15:20:15.603|9122=15:20:15.601|15=GBP|276=A|269=0|280=1GBP/USD.5M@BAR.7.RFQ|278=b-47005812040140660-4|270=1.31014|271=5000000|272=20190307|273=15:20:16.102|9122=15:20:16.076|15=GBP|276=A|110=3000000|269=0|280=529|278=b-47005812040140660-5|270=1.31009|271=4000000|272=20190307|273=15:20:15.510|9122=15:20:13.135|15=GBP|276=A|269=0|280=5165|278=b-47005812040140660-6|270=1.31008|271=4000000|272=20190307|273=15:20:15.510|9122=15:20:13.135|15=GBP|276=A|269=0|280=5249|278=b-47005812040140660-7|270=1.31007|271=4000000|272=20190307|273=15:20:15.510|9122=15:20:13.135|15=GBP|276=A|269=0|280=2BNP53|278=b-47005812040140660-8|270=1.31007|271=10000000|272=20190307|273=15:20:15.603|9122=15:20:15.601|15=GBP|276=A|269=0|280=7COBA0B1|278=b-47005812040140660-9|270=1.31005|271=1000000|272=20190307|273=15:20:16.515|9122=15:20:16.513|15=GBP|276=A|269=0|280=7COBA0B2|278=b-47005812040140660-10|270=1.31004|271=3000000|272=20190307|273=15:20:16.515|9122=15:20:16.513|15=GBP|276=A|269=1|280=1GBP/USD.1M@BAR.7.RFQ|278=o-47005812040140660-1|270=1.3103|271=1000000|272=20190307|273=15:20:16.101|9122=15:20:16.076|15=GBP|276=A|110=0|269=1|280=1GBP/USD.5M@BAR.7.RFQ|278=o-47005812040140660-2|270=1.31032|271=5000000|272=20190307|273=15:20:16.102|9122=15:20:16.076|15=GBP|276=A|110=3000000|269=1|280=2BNP51|278=o-47005812040140660-3|270=1.31033|271=5000000|272=20190307|273=15:20:15.603|9122=15:20:15.601|15=GBP|276=A|269=1|280=7COBA0O1|278=o-47005812040140660-4|270=1.31034|271=1000000|272=20190307|273=15:20:16.515|9122=15:20:16.513|15=GBP|276=A|269=1|280=519|278=o-47005812040140660-5|270=1.31036|271=4000000|272=20190307|273=15:20:15.510|9122=15:20:15.475|15=GBP|276=A|269=1|280=2BNP52|278=o-47005812040140660-6|270=1.31036|271=6000000|272=20190307|273=15:20:15.603|9122=15:20:15.601|15=GBP|276=A|269=1|280=7COBA0O2|278=o-47005812040140660-7|270=1.31036|271=3000000|272=20190307|273=15:20:16.515|9122=15:20:16.513|15=GBP|276=A|269=1|280=9MS0a1|278=o-47005812040140660-8|270=1.31036|271=1000000|272=20190307|273=15:20:18.043|9122=15:20:18.042|15=GBP|276=A|269=1|280=5198|278=o-47005812040140660-9|270=1.31037|271=4000000|272=20190307|273=15:20:15.510|9122=15:20:15.475|15=GBP|276=A|269=1|280=7COBA0O3|278=o-47005812040140660-10|270=1.31037|271=5000000|272=20190307|273=15:20:16.515|9122=15:20:16.513|15=GBP|276=A|10=059|
8=FIX.4.4|9=0853|35=X|49=LFX|56=MKT.UAT.QPU600|34=3|52=20190307-15:20:20.427|262=MDReqID_1|55=GBP/USD|64=20190311|268=7|279=1|269=0|278=b-47005814236839174-3|280=2BNP51|270=1.31013|272=20190307|273=15:20:20.307|9122=15:20:20.301|290=2|279=1|269=0|278=b-47005814236839174-4|280=2BNP52|270=1.3101|272=20190307|273=15:20:20.307|9122=15:20:20.301|290=3|279=1|269=0|278=b-47005814236839174-8|280=2BNP53|270=1.31006|272=20190307|273=15:20:20.307|9122=15:20:20.301|290=7|279=1|269=1|278=o-47005814236839174-1|280=2BNP51|270=1.31026|272=20190307|273=15:20:20.307|9122=15:20:20.301|290=0|279=1|269=1|278=o-47005814236839174-2|280=2BNP52|270=1.31029|272=20190307|273=15:20:20.307|9122=15:20:20.301|290=1|279=0|269=1|278=o-47005814236839174-6|280=2BNP53|270=1.31035|271=10000000|15=GBP|272=20190307|273=15:20:20.307|9122=15:20:20.301|276=A|282=QPU08|290=5|279=2|269=1|280=7COBA0O3|10=028|
8=FIX.4.4|9=0687|35=X|49=LFX|56=MKT.UAT.QPU600|34=4|52=20190307-15:20:20.430|262=MDReqID_1|55=GBP/USD|64=20190311|268=6|279=1|269=0|278=b-47005814240487320-8|280=7COBA0B1|270=1.31006|272=20190307|273=15:20:20.233|9122=15:20:20.232|290=7|279=0|269=0|278=b-47005814240487320-10|280=9MS0b1|270=1.31004|271=1000000|15=GBP|272=20190307|273=15:20:18.043|9122=15:20:18.042|276=A|282=QPU47|290=9|279=2|269=0|280=7COBA0B2|279=1|269=1|278=o-47005814240487320-6|280=7COBA0O2|270=1.31035|272=20190307|273=15:20:20.233|9122=15:20:20.232|290=5|279=0|269=1|278=o-47005814240487320-10|280=7COBA0O3|270=1.31036|271=5000000|15=GBP|272=20190307|273=15:20:20.233|9122=15:20:20.232|276=A|282=QPU17|290=9|279=2|269=1|280=5198|10=164|
8=FIX.4.4|9=0333|35=X|49=LFX|56=MKT.UAT.QPU600|34=5|52=20190307-15:20:20.431|262=MDReqID_1|55=GBP/USD|64=20190311|268=2|279=1|269=0|278=b-47005814240629948-6|280=9MS0b1|270=1.31009|272=20190307|273=15:20:20.260|9122=15:20:20.259|290=5|279=1|269=1|278=o-47005814240629948-7|280=9MS0a1|270=1.31035|272=20190307|273=15:20:20.260|9122=15:20:20.259|290=6|10=042|
8=FIX.4.4|9=0545|35=X|49=LFX|56=MKT.UAT.QPU600|34=6|52=20190307-15:20:20.631|262=MDReqID_1|55=GBP/USD|64=20190311|268=5|279=0|269=1|278=o-47005814440713226-4|280=5195|270=1.31031|271=4000000|272=20190307|273=15:20:20.460|9122=15:20:20.425|276=A|282=QPU90|290=3|279=0|269=1|278=o-47005814440713226-6|280=5198|270=1.31032|271=4000000|272=20190307|273=15:20:20.460|9122=15:20:20.425|276=A|282=QPU90|290=5|279=1|269=1|278=o-47005814440713226-7|280=519|270=1.31033|272=20190307|273=15:20:20.460|9122=15:20:20.425|290=6|279=2|269=1|280=7COBA0O3|279=2|269=1|280=2BNP53|10=055|
8=FIX.4.4|9=0397|35=X|49=LFX|56=MKT.UAT.QPU600|34=7|52=20190307-15:20:20.831|262=MDReqID_1|55=GBP/USD|64=20190311|268=3|279=1|269=0|278=b-47005814640644874-8|280=7COBA0B1|270=1.31008|272=20190307|273=15:20:20.753|9122=15:20:20.753|290=7|279=0|269=1|278=o-47005814640644874-10|280=2BNP53|270=1.31035|271=10000000|15=GBP|272=20190307|273=15:20:20.307|9122=15:20:20.301|276=A|282=QPU08|290=9|279=2|269=1|280=7COBA0O2|10=185|
8=FIX.4.4|9=0611|35=X|49=LFX|56=MKT.UAT.QPU600|34=8|52=20190307-15:20:20.831|262=MDReqID_1|55=GBP/USD|64=20190311|268=6|279=0|269=1|278=o-47005814640705623-8|280=7COBA0O2|270=1.31035|271=3000000|15=GBP|272=20190307|273=15:20:20.754|9122=15:20:20.753|276=A|282=QPU17|290=7|279=0|269=1|278=o-47005814640705623-9|280=7COBA0O3|270=1.31036|271=5000000|15=GBP|272=20190307|273=15:20:20.754|9122=15:20:20.753|276=A|282=QPU17|290=8|279=0|269=1|278=o-47005814640705623-10|280=5125|270=1.31036|271=4000000|272=20190307|273=15:20:20.815|9122=15:20:20.780|276=A|282=QPU90|290=9|279=2|269=1|280=5195|279=2|269=1|280=5198|279=2|269=1|280=519|10=104|
8=FIX.4.4|9=0547|35=X|49=LFX|56=MKT.UAT.QPU600|34=9|52=20190307-15:20:21.031|262=MDReqID_1|55=GBP/USD|64=20190311|268=5|279=0|269=1|278=o-47005814840659371-4|280=528|270=1.31031|271=4000000|272=20190307|273=15:20:20.905|9122=15:20:20.870|276=A|282=QPU90|290=3|279=0|269=1|278=o-47005814840659371-6|280=5243|270=1.31032|271=4000000|272=20190307|273=15:20:20.905|9122=15:20:20.870|276=A|282=QPU90|290=5|279=1|269=1|278=o-47005814840659371-7|280=5125|270=1.31033|272=20190307|273=15:20:20.905|9122=15:20:20.870|290=6|279=2|269=1|280=7COBA0O2|279=2|269=1|280=7COBA0O3|10=236|
8=FIX.4.4|9=0624|35=X|49=LFX|56=MKT.UAT.QPU600|34=10|52=20190307-15:20:21.231|262=MDReqID_1|55=GBP/USD|64=20190311|268=4|279=1|269=0|278=b-47005815040759515-1|280=1GBP/USD.1M@BAR.7.RFQ|270=1.31015|272=20190307|273=15:20:21.129|9122=15:20:21.092|290=0|279=1|269=0|278=b-47005815040759515-3|280=1GBP/USD.5M@BAR.7.RFQ|270=1.31013|272=20190307|273=15:20:21.131|9122=15:20:21.092|290=2|279=1|269=1|278=o-47005815040759515-1|280=1GBP/USD.1M@BAR.7.RFQ|270=1.31025|272=20190307|273=15:20:21.129|9122=15:20:21.092|290=0|279=1|269=1|278=o-47005815040759515-3|280=1GBP/USD.5M@BAR.7.RFQ|270=1.31027|272=20190307|273=15:20:21.131|9122=15:20:21.092|290=2|10=192|
8=FIX.4.4|9=0854|35=X|49=LFX|56=MKT.UAT.QPU600|34=11|52=20190307-15:20:21.427|262=MDReqID_1|55=GBP/USD|64=20190311|268=7|279=1|269=0|278=b-47005815237019159-5|280=2BNP51|270=1.31009|272=20190307|273=15:20:21.378|9122=15:20:21.301|290=4|279=1|269=0|278=b-47005815237019159-8|280=2BNP52|270=1.31008|272=20190307|273=15:20:21.378|9122=15:20:21.301|290=7|279=0|269=0|278=b-47005815237019159-10|280=7COBA0B2|270=1.31006|271=3000000|15=GBP|272=20190307|273=15:20:20.754|9122=15:20:20.753|276=A|282=QPU17|290=9|279=2|269=0|280=2BNP53|279=1|269=1|278=o-47005815237019159-1|280=2BNP51|270=1.3102|272=20190307|273=15:20:21.378|9122=15:20:21.301|290=0|279=1|269=1|278=o-47005815237019159-2|280=2BNP52|270=1.31023|272=20190307|273=15:20:21.378|9122=15:20:21.301|290=1|279=1|269=1|278=o-47005815237019159-5|280=2BNP53|270=1.31027|272=20190307|273=15:20:21.378|9122=15:20:21.301|290=4|10=107|
8=FIX.4.4|9=0691|35=X|49=LFX|56=MKT.UAT.QPU600|34=12|52=20190307-15:20:21.431|262=MDReqID_1|55=GBP/USD|64=20190311|268=6|279=1|269=0|278=b-47005815240851084-9|280=7COBA0B1|270=1.31005|272=20190307|273=15:20:21.269|9122=15:20:21.268|290=8|279=0|269=0|278=b-47005815240851084-10|280=2BNP53|270=1.31004|271=10000000|15=GBP|272=20190307|273=15:20:21.378|9122=15:20:21.301|276=A|282=QPU08|290=9|279=2|269=0|280=7COBA0B2|279=1|269=1|278=o-47005815240851084-7|280=7COBA0O1|270=1.31031|272=20190307|273=15:20:21.269|9122=15:20:21.268|290=6|279=0|269=1|278=o-47005815240851084-10|280=7COBA0O2|270=1.31033|271=3000000|15=GBP|272=20190307|273=15:20:21.269|9122=15:20:21.268|276=A|282=QPU17|290=9|279=2|269=1|280=9MS0a1|10=220|
8=FIX.4.4|9=0455|35=X|49=LFX|56=MKT.UAT.QPU600|34=13|52=20190307-15:20:21.431|262=MDReqID_1|55=GBP/USD|64=20190311|268=4|279=0|269=0|278=b-47005815240912087-10|280=7COBA0B2|270=1.31003|271=3000000|15=GBP|272=20190307|273=15:20:21.269|9122=15:20:21.268|276=A|282=QPU17|290=9|279=2|269=0|280=9MS0b1|279=0|269=1|278=o-47005815240912087-5|280=9MS0a1|270=1.31027|271=1000000|15=GBP|272=20190307|273=15:20:21.248|9122=15:20:21.247|276=A|282=QPU47|290=4|279=2|269=1|280=7COBA0O2|10=094|
8=FIX.4.4|9=1094|35=X|49=LFX|56=MKT.UAT.QPU600|34=14|52=20190307-15:20:21.431|262=MDReqID_1|55=GBP/USD|64=20190311|268=12|279=0|269=0|278=b-47005815240883297-8|280=7COBA0B3|270=1.31003|271=5000000|15=GBP|272=20190307|273=15:20:21.269|9122=15:20:21.268|276=A|282=QPU17|290=7|279=0|269=0|278=b-47005815240883297-9|280=9MS0b1|270=1.31001|271=1000000|15=GBP|272=20190307|273=15:20:21.248|9122=15:20:21.247|276=A|282=QPU47|290=8|279=0|269=0|278=b-47005815240883297-10|280=584|270=1.30999|271=4000000|272=20190307|273=15:20:21.310|9122=15:20:21.275|276=A|282=QPU90|290=9|279=2|269=0|280=5165|279=2|269=0|280=5249|279=2|269=0|280=529|279=0|269=1|278=o-47005815240883297-2|280=5264|270=1.31021|271=4000000|272=20190307|273=15:20:21.310|9122=15:20:21.230|276=A|282=QPU90|290=1|279=0|269=1|278=o-47005815240883297-3|280=580|270=1.31022|271=4000000|272=20190307|273=15:20:21.310|9122=15:20:21.230|276=A|282=QPU90|290=2|279=0|269=1|278=o-47005815240883297-4|280=5119|270=1.31023|271=4000000|272=20190307|273=15:20:21.310|9122=15:20:21.230|276=A|282=QPU90|290=3|279=2|269=1|280=5243|279=2|269=1|280=5125|279=2|269=1|280=528|10=222|
8=FIX.4.4|9=0572|35=X|49=LFX|56=MKT.UAT.QPU600|34=15|52=20190307-15:20:21.631|262=MDReqID_1|55=GBP/USD|64=20190311|268=4|279=1|269=0|278=b-47005815440943615-6|280=7COBA0B1|270=1.31003|272=20190307|273=15:20:21.476|9122=15:20:21.475|290=5|279=1|269=0|278=b-47005815440943615-7|280=7COBA0B2|270=1.31002|272=20190307|273=15:20:21.476|9122=15:20:21.475|290=6|279=1|269=0|278=b-47005815440943615-9|280=7COBA0B3|270=1.31001|272=20190307|273=15:20:21.476|9122=15:20:21.475|290=8|279=1|269=1|278=o-47005815440943615-10|280=7COBA0O1|270=1.3103|272=20190307|273=15:20:21.476|9122=15:20:21.475|290=9|10=069|
8=FIX.4.4|9=0623|35=X|49=LFX|56=MKT.UAT.QPU600|34=16|52=20190307-15:20:21.831|262=MDReqID_1|55=GBP/USD|64=20190311|268=5|279=1|269=0|278=b-47005815640846136-7|280=7COBA0B1|270=1.31001|272=20190307|273=15:20:21.672|9122=15:20:21.671|290=6|279=1|269=0|278=b-47005815640846136-9|280=7COBA0B2|270=1.30999|272=20190307|273=15:20:21.672|9122=15:20:21.671|290=8|279=0|269=0|278=b-47005815640846136-10|280=5253|270=1.30998|271=4000000|272=20190307|273=15:20:21.310|9122=15:20:21.275|276=A|282=QPU90|290=9|279=2|269=0|280=7COBA0B3|279=1|269=1|278=o-47005815640846136-10|280=7COBA0O1|270=1.31028|272=20190307|273=15:20:21.672|9122=15:20:21.671|290=9|10=017|
8=FIX.4.4|9=0624|35=X|49=LFX|56=MKT.UAT.QPU600|34=17|52=20190307-15:20:22.231|262=MDReqID_1|55=GBP/USD|64=20190311|268=4|279=1|269=0|278=b-47005816040863911-3|280=1GBP/USD.1M@BAR.7.RFQ|270=1.31005|272=20190307|273=15:20:22.113|9122=15:20:22.088|290=2|279=1|269=0|278=b-47005816040863911-5|280=1GBP/USD.5M@BAR.7.RFQ|270=1.31003|272=20190307|273=15:20:22.188|9122=15:20:22.091|290=4|279=1|269=1|278=o-47005816040863911-1|280=1GBP/USD.1M@BAR.7.RFQ|270=1.31015|272=20190307|273=15:20:22.113|9122=15:20:22.088|290=0|279=1|269=1|278=o-47005816040863911-2|280=1GBP/USD.5M@BAR.7.RFQ|270=1.31017|272=20190307|273=15:20:22.188|9122=15:20:22.091|290=1|10=216|
8=FIX.4.4|9=0855|35=X|49=LFX|56=MKT.UAT.QPU600|34=18|52=20190307-15:20:22.428|262=MDReqID_1|55=GBP/USD|64=20190311|268=7|279=1|269=0|278=b-47005816237602093-2|280=2BNP51|270=1.31004|272=20190307|273=15:20:22.303|9122=15:20:22.301|290=1|279=1|269=0|278=b-47005816237602093-6|280=2BNP52|270=1.31001|272=20190307|273=15:20:22.303|9122=15:20:22.301|290=5|279=0|269=0|278=b-47005816237602093-10|280=7COBA0B3|270=1.30998|271=5000000|15=GBP|272=20190307|273=15:20:21.672|9122=15:20:21.671|276=A|282=QPU17|290=9|279=2|269=0|280=2BNP53|279=1|269=1|278=o-47005816237602093-2|280=2BNP51|270=1.31016|272=20190307|273=15:20:22.303|9122=15:20:22.301|290=1|279=1|269=1|278=o-47005816237602093-4|280=2BNP52|270=1.31018|272=20190307|273=15:20:22.303|9122=15:20:22.301|290=3|279=1|269=1|278=o-47005816237602093-7|280=2BNP53|270=1.31022|272=20190307|273=15:20:22.303|9122=15:20:22.301|290=6|10=105|
8=FIX.4.4|9=0589|35=X|49=LFX|56=MKT.UAT.QPU600|34=19|52=20190307-15:20:22.431|262=MDReqID_1|55=GBP/USD|64=20190311|268=6|279=0|269=1|278=o-47005816241037497-6|280=5211|270=1.31026|271=4000000|272=20190307|273=15:20:22.330|9122=15:20:22.295|276=A|282=QPU90|290=5|279=0|269=1|278=o-47005816241037497-8|280=5109|270=1.31027|271=4000000|272=20190307|273=15:20:22.330|9122=15:20:22.295|276=A|282=QPU90|290=7|279=0|269=1|278=o-47005816241037497-10|280=520|270=1.31028|271=4000000|272=20190307|273=15:20:22.330|9122=15:20:22.295|276=A|282=QPU90|290=9|279=2|269=1|280=5264|279=2|269=1|280=5119|279=2|269=1|280=580|10=009|
8=FIX.4.4|9=0545|35=X|49=LFX|56=MKT.UAT.QPU600|34=20|52=20190307-15:20:22.627|262=MDReqID_1|55=GBP/USD|64=20190311|268=11|279=2|269=0|280=5253|279=2|269=0|280=2BNP52|279=2|269=0|280=2BNP51|279=2|269=0|280=1GBP/USD.5M@BAR.7.RFQ|279=2|269=0|280=1GBP/USD.1M@BAR.7.RFQ|279=0|269=1|278=o-47005816437550365-6|280=7COBA0O2|270=1.31029|271=3000000|15=GBP|272=20190307|273=15:20:21.672|9122=15:20:21.671|276=A|282=QPU17|290=5|279=2|269=1|280=2BNP52|279=2|269=1|280=2BNP51|279=2|269=1|280=2BNP53|279=2|269=1|280=1GBP/USD.5M@BAR.7.RFQ|279=2|269=1|280=1GBP/USD.1M@BAR.7.RFQ|10=046|
8=FIX.4.4|9=0688|35=X|49=LFX|56=MKT.UAT.QPU600|34=21|52=20190307-15:20:22.631|262=MDReqID_1|55=GBP/USD|64=20190311|268=5|279=1|269=0|278=b-47005816441153727-1|280=7COBA0B1|270=1.31004|272=20190307|273=15:20:22.542|9122=15:20:22.541|290=0|279=1|269=0|278=b-47005816441153727-2|280=7COBA0B2|270=1.31002|272=20190307|273=15:20:22.542|9122=15:20:22.541|290=1|279=1|269=0|278=b-47005816441153727-4|280=7COBA0B3|270=1.31001|272=20190307|273=15:20:22.542|9122=15:20:22.541|290=3|279=1|269=1|278=o-47005816441153727-5|280=7COBA0O1|270=1.3103|272=20190307|273=15:20:22.542|9122=15:20:22.541|290=4|279=1|269=1|278=o-47005816441153727-6|280=7COBA0O2|270=1.31031|272=20190307|273=15:20:22.542|9122=15:20:22.541|290=5|10=121|
8=FIX.4.4|9=0991|35=X|49=LFX|56=MKT.UAT.QPU600|34=22|52=20190307-15:20:22.631|262=MDReqID_1|55=GBP/USD|64=20190311|268=10|279=1|269=0|278=b-47005816441236271-1|280=9MS0b1|270=1.31006|272=20190307|273=15:20:22.541|9122=15:20:22.509|290=0|279=0|269=0|278=b-47005816441236271-5|280=583|270=1.30999|271=4000000|272=20190307|273=15:20:22.615|9122=15:20:22.580|276=A|282=QPU90|290=4|279=2|269=0|280=584|279=0|269=1|278=o-47005816441236271-3|280=5257|270=1.31031|271=4000000|272=20190307|273=15:20:22.615|9122=15:20:22.455|276=A|282=QPU90|290=2|279=1|269=1|278=o-47005816441236271-4|280=9MS0a1|270=1.31032|272=20190307|273=15:20:22.541|9122=15:20:22.509|290=3|279=0|269=1|278=o-47005816441236271-5|280=7COBA0O3|270=1.31032|271=5000000|15=GBP|272=20190307|273=15:20:22.542|9122=15:20:22.541|276=A|282=QPU17|290=4|279=0|269=1|278=o-47005816441236271-6|280=5169|270=1.31032|271=4000000|272=20190307|273=15:20:22.615|9122=15:20:22.455|276=A|282=QPU90|290=5|279=2|269=1|280=520|279=2|269=1|280=5211|279=2|269=1|280=5109|10=152|
8=FIX.4.4|9=0572|35=X|49=LFX|56=MKT.UAT.QPU600|34=23|52=20190307-15:20:22.831|262=MDReqID_1|55=GBP/USD|64=20190311|268=4|279=1|269=0|278=b-47005816641195681-2|280=7COBA0B1|270=1.31006|272=20190307|273=15:20:22.692|9122=15:20:22.691|290=1|279=1|269=0|278=b-47005816641195681-3|280=7COBA0B2|270=1.31004|272=20190307|273=15:20:22.692|9122=15:20:22.691|290=2|279=1|269=0|278=b-47005816641195681-4|280=7COBA0B3|270=1.31003|272=20190307|273=15:20:22.692|9122=15:20:22.691|290=3|279=1|269=1|278=o-47005816641195681-5|280=7COBA0O2|270=1.31032|272=20190307|273=15:20:22.692|9122=15:20:22.691|290=4|10=086|
8=FIX.4.4|9=0523|35=X|49=LFX|56=MKT.UAT.QPU600|34=24|52=20190307-15:20:22.831|262=MDReqID_1|55=GBP/USD|64=20190311|268=4|279=0|269=0|278=b-47005816641227384-1|280=5149|270=1.31009|271=4000000|272=20190307|273=15:20:22.825|9122=15:20:22.790|276=A|282=QPU90|290=0|279=0|269=0|278=b-47005816641227384-2|280=5143|270=1.31008|271=4000000|272=20190307|273=15:20:22.825|9122=15:20:22.790|276=A|282=QPU90|290=1|279=1|269=0|278=b-47005816641227384-3|280=583|270=1.31007|272=20190307|273=15:20:22.825|9122=15:20:22.790|290=2|279=2|269=0|280=7COBA0B3|10=235|
8=FIX.4.4|9=0898|35=X|49=LFX|56=MKT.UAT.QPU600|34=25|52=20190307-15:20:23.231|262=MDReqID_1|55=GBP/USD|64=20190311|268=10|279=0|269=0|278=b-47005817041243633-1|280=5269|270=1.31009|271=4000000|272=20190307|273=15:20:23.020|9122=15:20:22.985|276=A|282=QPU90|290=0|279=0|269=0|278=b-47005817041243633-2|280=5202|270=1.31008|271=4000000|272=20190307|273=15:20:23.020|9122=15:20:22.985|276=A|282=QPU90|290=1|279=0|269=0|278=b-47005817041243633-3|280=5177|270=1.31007|271=4000000|272=20190307|273=15:20:23.020|9122=15:20:22.985|276=A|282=QPU90|290=2|279=2|269=0|280=583|279=2|269=0|280=5143|279=2|269=0|280=5149|279=1|269=1|278=o-47005817041243633-4|280=7COBA0O1|270=1.31032|272=20190307|273=15:20:23.075|9122=15:20:23.068|290=3|279=0|269=1|278=o-47005817041243633-5|280=5203|270=1.31033|271=4000000|272=20190307|273=15:20:23.020|9122=15:20:22.455|276=A|282=QPU90|290=4|279=2|269=1|280=7COBA0O2|279=2|269=1|280=7COBA0O3|10=102|
8=FIX.4.4|9=1525|35=X|49=LFX|56=MKT.UAT.QPU600|34=26|52=20190307-15:20:23.431|262=MDReqID_1|55=GBP/USD|64=20190311|268=9|279=0|269=0|278=b-47005817241370021-1|280=2BNP51|270=1.31014|271=5000000|15=GBP|272=20190307|273=15:20:22.503|9122=15:20:22.501|276=A|282=QPU08|290=0|279=0|269=0|278=b-47005817241370021-2|280=2BNP52|270=1.31011|271=6000000|15=GBP|272=20190307|273=15:20:22.503|9122=15:20:22.501|276=A|282=QPU08|290=1|279=0|269=0|278=b-47005817241370021-5|280=2BNP53|270=1.31007|271=10000000|15=GBP|272=20190307|273=15:20:22.503|9122=15:20:22.501|276=A|282=QPU08|290=4|279=0|269=0|278=b-47005817241370021-9|280=1GBP/USD.1M@BAR.7.RFQ|270=1.31006|271=1000000|110=0|15=GBP|272=20190307|273=15:20:23.323|9122=15:20:23.084|276=A|282=QPU04|290=8|279=0|269=1|278=o-47005817241370021-1|280=1GBP/USD.1M@BAR.7.RFQ|270=1.31025|271=1000000|110=0|15=GBP|272=20190307|273=15:20:23.323|9122=15:20:23.084|276=A|282=QPU04|290=0|279=0|269=1|278=o-47005817241370021-2|280=2BNP51|270=1.31026|271=5000000|15=GBP|272=20190307|273=15:20:22.503|9122=15:20:22.501|276=A|282=QPU08|290=1|279=0|269=1|278=o-47005817241370021-3|280=1GBP/USD.5M@BAR.7.RFQ|270=1.31027|271=5000000|110=3000000|15=GBP|272=20190307|273=15:20:23.329|9122=15:20:23.084|276=A|282=QPU04|290=2|279=0|269=1|278=o-47005817241370021-4|280=2BNP52|270=1.31028|271=6000000|15=GBP|272=20190307|273=15:20:22.503|9122=15:20:22.501|276=A|282=QPU08|290=3|279=0|269=1|278=o-47005817241370021-9|280=2BNP53|270=1.31033|271=10000000|15=GBP|272=20190307|273=15:20:22.503|9122=15:20:22.501|276=A|282=QPU08|290=8|10=085|
8=FIX.4.4|9=0812|35=X|49=LFX|56=MKT.UAT.QPU600|34=27|52=20190307-15:20:23.831|262=MDReqID_1|55=GBP/USD|64=20190311|268=8|279=0|269=0|278=b-47005817641480502-8|280=1GBP/USD.5M@BAR.7.RFQ|270=1.31004|271=5000000|110=3000000|15=GBP|272=20190307|273=15:20:23.329|9122=15:20:23.084|276=A|282=QPU04|290=7|279=0|269=0|278=b-47005817641480502-9|280=7COBA0B3|270=1.31003|271=5000000|15=GBP|272=20190307|273=15:20:23.075|9122=15:20:23.068|276=A|282=QPU17|290=8|279=0|269=0|278=b-47005817641480502-10|280=5110|270=1.30999|271=4000000|272=20190307|273=15:20:23.771|9122=15:20:23.735|276=A|282=QPU90|290=9|279=2|269=0|280=5177|279=2|269=0|280=5202|279=2|269=0|280=5269|279=0|269=1|278=o-47005817641480502-10|280=7COBA0O2|270=1.31033|271=3000000|15=GBP|272=20190307|273=15:20:23.075|9122=15:20:23.068|276=A|282=QPU17|290=9|279=2|269=1|280=5203|10=193|
8=FIX.4.4|9=0388|35=X|49=LFX|56=MKT.UAT.QPU600|34=28|52=20190307-15:20:24.232|262=MDReqID_1|55=GBP/USD|64=20190311|268=3|279=1|269=0|278=b-47005818041678530-9|280=7COBA0B3|270=1.31004|272=20190307|273=15:20:24.131|9122=15:20:24.130|290=8|279=0|269=1|278=o-47005818041678530-10|280=5203|270=1.31033|271=4000000|272=20190307|273=15:20:23.771|9122=15:20:22.455|276=A|282=QPU90|290=9|279=2|269=1|280=7COBA0O2|10=141|
8=FIX.4.4|9=0221|35=X|49=LFX|56=MKT.UAT.QPU600|34=29|52=20190307-15:20:25.232|262=MDReqID_1|55=GBP/USD|64=20190311|268=1|279=1|269=0|278=b-47005819042030424-9|280=7COBA0B3|270=1.31003|272=20190307|273=15:20:25.176|9122=15:20:25.175|290=8|10=091|
8=FIX.4.4|9=0333|35=X|49=LFX|56=MKT.UAT.QPU600|34=30|52=20190307-15:20:25.232|262=MDReqID_1|55=GBP/USD|64=20190311|268=2|279=1|269=0|278=b-47005819042196726-8|280=9MS0b1|270=1.31004|272=20190307|273=15:20:25.182|9122=15:20:25.181|290=7|279=1|269=1|278=o-47005819042196726-5|280=9MS0a1|270=1.3103|272=20190307|273=15:20:25.182|9122=15:20:25.181|290=4|10=044|
8=FIX.4.4|9=0572|35=X|49=LFX|56=MKT.UAT.QPU600|34=31|52=20190307-15:20:25.432|262=MDReqID_1|55=GBP/USD|64=20190311|268=4|279=1|269=0|278=b-47005819242057697-7|280=7COBA0B1|270=1.31004|272=20190307|273=15:20:25.259|9122=15:20:25.259|290=6|279=1|269=0|278=b-47005819242057697-8|280=7COBA0B2|270=1.31003|272=20190307|273=15:20:25.259|9122=15:20:25.259|290=7|279=1|269=0|278=b-47005819242057697-9|280=7COBA0B3|270=1.31002|272=20190307|273=15:20:25.259|9122=15:20:25.259|290=8|279=1|269=1|278=o-47005819242057697-7|280=7COBA0O1|270=1.31031|272=20190307|273=15:20:25.259|9122=15:20:25.259|290=6|10=149|
8=FIX.4.4|9=0627|35=X|49=LFX|56=MKT.UAT.QPU600|34=32|52=20190307-15:20:26.432|262=MDReqID_1|55=GBP/USD|64=20190311|268=5|279=1|269=0|278=b-47005820242158694-8|280=7COBA0B2|270=1.31002|272=20190307|273=15:20:26.261|9122=15:20:26.261|290=7|279=1|269=0|278=b-47005820242158694-9|280=7COBA0B3|270=1.31001|272=20190307|273=15:20:26.261|9122=15:20:26.261|290=8|279=1|269=1|278=o-47005820242158694-6|280=7COBA0O1|270=1.3103|272=20190307|273=15:20:26.261|9122=15:20:26.261|290=5|279=0|269=1|278=o-47005820242158694-9|280=7COBA0O2|270=1.31032|271=3000000|15=GBP|272=20190307|273=15:20:26.261|9122=15:20:26.261|276=A|282=QPU17|290=8|279=2|269=1|280=5203|10=242|
8=FIX.4.4|9=0494|35=X|49=LFX|56=MKT.UAT.QPU600|34=33|52=20190307-15:20:26.432|262=MDReqID_1|55=GBP/USD|64=20190311|268=4|279=0|269=1|278=o-47005820242209665-3|280=5203|270=1.31026|271=4000000|272=20190307|273=15:20:26.385|9122=15:20:26.350|276=A|282=QPU90|290=2|279=1|269=1|278=o-47005820242209665-5|280=5169|270=1.31027|272=20190307|273=15:20:26.385|9122=15:20:26.350|290=4|279=1|269=1|278=o-47005820242209665-7|280=5257|270=1.31028|272=20190307|273=15:20:26.385|9122=15:20:26.350|290=6|279=2|269=1|280=2BNP53|10=093|
8=FIX.4.4|9=0398|35=X|49=LFX|56=MKT.UAT.QPU600|34=34|52=20190307-15:20:26.632|262=MDReqID_1|55=GBP/USD|64=20190311|268=3|279=1|269=1|278=o-47005820442344746-9|280=7COBA0O1|270=1.31031|272=20190307|273=15:20:26.608|9122=15:20:26.607|290=8|279=0|269=1|278=o-47005820442344746-10|280=2BNP53|270=1.31033|271=10000000|15=GBP|272=20190307|273=15:20:22.503|9122=15:20:22.501|276=A|282=QPU08|290=9|279=2|269=1|280=7COBA0O2|10=003|
8=FIX.4.4|9=0829|35=X|49=LFX|56=MKT.UAT.QPU600|34=35|52=20190307-15:20:26.832|262=MDReqID_1|55=GBP/USD|64=20190311|268=8|279=1|269=0|278=b-47005820642463528-9|280=9MS0b1|270=1.31|272=20190307|273=15:20:26.759|9122=15:20:26.757|290=8|279=1|269=1|278=o-47005820642463528-3|280=9MS0a1|270=1.31026|272=20190307|273=15:20:26.759|9122=15:20:26.757|290=2|279=0|269=1|278=o-47005820642463528-7|280=5195|270=1.31031|271=4000000|272=20190307|273=15:20:26.770|9122=15:20:26.735|276=A|282=QPU90|290=6|279=0|269=1|278=o-47005820642463528-8|280=5198|270=1.31032|271=4000000|272=20190307|273=15:20:26.770|9122=15:20:26.735|276=A|282=QPU90|290=7|279=0|269=1|278=o-47005820642463528-10|280=7COBA0O2|270=1.31033|271=3000000|15=GBP|272=20190307|273=15:20:26.608|9122=15:20:26.607|276=A|282=QPU17|290=9|279=2|269=1|280=5169|279=2|269=1|280=5257|279=2|269=1|280=5203|10=119|
8=FIX.4.4|9=0454|35=X|49=LFX|56=MKT.UAT.QPU600|34=36|52=20190307-15:20:27.232|262=MDReqID_1|55=GBP/USD|64=20190311|268=3|279=1|269=0|278=b-47005821042365971-8|280=7COBA0B3|270=1.31002|272=20190307|273=15:20:27.190|9122=15:20:27.186|290=7|279=1|269=1|278=o-47005821042365971-6|280=7COBA0O1|270=1.3103|272=20190307|273=15:20:27.190|9122=15:20:27.186|290=5|279=1|269=1|278=o-47005821042365971-9|280=7COBA0O2|270=1.31032|272=20190307|273=15:20:27.190|9122=15:20:27.186|290=8|10=172|
8=FIX.4.4|9=0793|35=X|49=LFX|56=MKT.UAT.QPU600|34=37|52=20190307-15:20:27.429|262=MDReqID_1|55=GBP/USD|64=20190311|268=6|279=1|269=0|278=b-47005821239232119-1|280=2BNP51|270=1.31009|272=20190307|273=15:20:27.417|9122=15:20:27.405|290=0|279=1|269=0|278=b-47005821239232119-2|280=2BNP52|270=1.31007|272=20190307|273=15:20:27.417|9122=15:20:27.405|290=1|279=1|269=0|278=b-47005821239232119-6|280=2BNP53|270=1.31003|272=20190307|273=15:20:27.417|9122=15:20:27.405|290=5|279=1|269=1|278=o-47005821239232119-1|280=2BNP51|270=1.3102|272=20190307|273=15:20:27.417|9122=15:20:27.405|290=0|279=1|269=1|278=o-47005821239232119-2|280=2BNP52|270=1.31022|272=20190307|273=15:20:27.417|9122=15:20:27.405|290=1|279=1|269=1|278=o-47005821239232119-5|280=2BNP53|270=1.31026|272=20190307|273=15:20:27.417|9122=15:20:27.405|290=4|10=088|
8=FIX.4.4|9=0495|35=X|49=LFX|56=MKT.UAT.QPU600|34=38|52=20190307-15:20:27.433|262=MDReqID_1|55=GBP/USD|64=20190311|268=4|279=0|269=1|278=o-47005821243379784-6|280=519|270=1.31026|271=4000000|272=20190307|273=15:20:27.426|9122=15:20:27.390|276=A|282=QPU90|290=5|279=1|269=1|278=o-47005821243379784-8|280=5198|270=1.31027|272=20190307|273=15:20:27.426|9122=15:20:27.390|290=7|279=1|269=1|278=o-47005821243379784-9|280=5195|270=1.31028|272=20190307|273=15:20:27.426|9122=15:20:27.390|290=8|279=2|269=1|280=7COBA0O2|10=250|
8=FIX.4.4|9=0855|35=X|49=LFX|56=MKT.UAT.QPU600|34=39|52=20190307-15:20:27.629|262=MDReqID_1|55=GBP/USD|64=20190311|268=7|279=1|269=0|278=b-47005821439414369-1|280=2BNP51|270=1.31014|272=20190307|273=15:20:27.503|9122=15:20:27.501|290=0|279=1|269=0|278=b-47005821439414369-2|280=2BNP52|270=1.31012|272=20190307|273=15:20:27.503|9122=15:20:27.501|290=1|279=1|269=0|278=b-47005821439414369-3|280=2BNP53|270=1.31007|272=20190307|273=15:20:27.503|9122=15:20:27.501|290=2|279=1|269=1|278=o-47005821439414369-4|280=2BNP51|270=1.31026|272=20190307|273=15:20:27.503|9122=15:20:27.501|290=3|279=1|269=1|278=o-47005821439414369-8|280=2BNP52|270=1.31028|272=20190307|273=15:20:27.503|9122=15:20:27.501|290=7|279=0|269=1|278=o-47005821439414369-10|280=7COBA0O2|270=1.31032|271=3000000|15=GBP|272=20190307|273=15:20:27.190|9122=15:20:27.186|276=A|282=QPU17|290=9|279=2|269=1|280=2BNP53|10=229|
8=FIX.4.4|9=0335|35=X|49=LFX|56=MKT.UAT.QPU600|34=40|52=20190307-15:20:27.633|262=MDReqID_1|55=GBP/USD|64=20190311|268=2|279=1|269=0|278=b-47005821442647087-5|280=9MS0b1|270=1.31006|272=20190307|273=15:20:27.443|9122=15:20:27.439|290=4|279=1|269=1|278=o-47005821442647087-10|280=9MS0a1|270=1.31032|272=20190307|273=15:20:27.443|9122=15:20:27.439|290=9|10=165|
8=FIX.4.4|9=0600|35=X|49=LFX|56=MKT.UAT.QPU600|34=41|52=20190307-15:20:27.633|262=MDReqID_1|55=GBP/USD|64=20190311|268=6|279=0|269=1|278=o-47005821442608084-6|280=5200|270=1.31031|271=4000000|272=20190307|273=15:20:27.510|9122=15:20:27.475|276=A|282=QPU90|290=5|279=0|269=1|278=o-47005821442608084-9|280=2BNP53|270=1.31032|271=10000000|15=GBP|272=20190307|273=15:20:27.503|9122=15:20:27.501|276=A|282=QPU08|290=8|279=0|269=1|278=o-47005821442608084-10|280=5145|270=1.31032|271=4000000|272=20190307|273=15:20:27.510|9122=15:20:27.475|276=A|282=QPU90|290=9|279=2|269=1|280=5195|279=2|269=1|280=5198|279=2|269=1|280=519|10=143|
8=FIX.4.4|9=0729|35=X|49=LFX|56=MKT.UAT.QPU600|34=42|52=20190307-15:20:28.230|262=MDReqID_1|55=GBP/USD|64=20190311|268=6|279=1|269=0|278=b-47005822039934743-1|280=2BNP51|270=1.31007|272=20190307|273=15:20:28.110|9122=15:20:28.103|290=0|279=1|269=0|278=b-47005822039934743-6|280=2BNP52|270=1.31004|272=20190307|273=15:20:28.110|9122=15:20:28.103|290=5|279=0|269=0|278=b-47005822039934743-10|280=5181|270=1.30998|271=4000000|272=20190307|273=15:20:27.510|9122=15:20:23.735|276=A|282=QPU90|290=9|279=2|269=0|280=2BNP53|279=1|269=1|278=o-47005822039934743-1|280=2BNP51|270=1.31023|272=20190307|273=15:20:28.110|9122=15:20:28.103|290=0|279=1|269=1|278=o-47005822039934743-3|280=2BNP52|270=1.31026|272=20190307|273=15:20:28.110|9122=15:20:28.103|290=2|10=234|
8=FIX.4.4|9=0493|35=X|49=LFX|56=MKT.UAT.QPU600|34=43|52=20190307-15:20:28.233|262=MDReqID_1|55=GBP/USD|64=20190311|268=4|279=0|269=1|278=o-47005822042752587-1|280=521|270=1.31021|271=4000000|272=20190307|273=15:20:28.205|9122=15:20:28.170|276=A|282=QPU90|290=0|279=1|269=1|278=o-47005822042752587-2|280=5145|270=1.31022|272=20190307|273=15:20:28.205|9122=15:20:28.170|290=1|279=1|269=1|278=o-47005822042752587-4|280=5200|270=1.31023|272=20190307|273=15:20:28.205|9122=15:20:28.170|290=3|279=2|269=1|280=2BNP53|10=254|
8=FIX.4.4|9=0861|35=X|49=LFX|56=MKT.UAT.QPU600|34=44|52=20190307-15:20:28.233|262=MDReqID_1|55=GBP/USD|64=20190311|268=7|279=1|269=0|278=b-47005822042856314-6|280=7COBA0B1|270=1.31001|272=20190307|273=15:20:28.230|9122=15:20:28.228|290=5|279=1|269=0|278=b-47005822042856314-7|280=7COBA0B2|270=1.31|272=20190307|273=15:20:28.230|9122=15:20:28.228|290=6|279=1|269=0|278=b-47005822042856314-9|280=7COBA0B3|270=1.30999|272=20190307|273=15:20:28.230|9122=15:20:28.228|290=8|279=1|269=1|278=o-47005822042856314-8|280=7COBA0O1|270=1.31028|272=20190307|273=15:20:28.230|9122=15:20:28.228|290=7|279=1|269=1|278=o-47005822042856314-9|280=7COBA0O2|270=1.31029|272=20190307|273=15:20:28.230|9122=15:20:28.228|290=8|279=0|269=1|278=o-47005822042856314-10|280=7COBA0O3|270=1.3103|271=5000000|15=GBP|272=20190307|273=15:20:28.230|9122=15:20:28.228|276=A|282=QPU17|290=9|279=2|269=1|280=9MS0a1|10=187|
8=FIX.4.4|9=0394|35=X|49=LFX|56=MKT.UAT.QPU600|34=45|52=20190307-15:20:28.233|262=MDReqID_1|55=GBP/USD|64=20190311|268=3|279=1|269=0|278=b-47005822042896890-9|280=9MS0b1|270=1.30998|272=20190307|273=15:20:28.112|9122=15:20:28.109|290=8|279=0|269=1|278=o-47005822042896890-10|280=9MS0a1|270=1.3103|271=1000000|15=GBP|272=20190307|273=15:20:28.112|9122=15:20:28.109|276=A|282=QPU47|290=9|279=2|269=1|280=7COBA0O3|10=128|
8=FIX.4.4|9=0738|35=X|49=LFX|56=MKT.UAT.QPU600|34=46|52=20190307-15:20:28.430|262=MDReqID_1|55=GBP/USD|64=20190311|268=6|279=1|269=0|278=b-47005822239596703-3|280=2BNP51|270=1.31003|272=20190307|273=15:20:28.305|9122=15:20:28.301|290=2|279=1|269=0|278=b-47005822239596703-5|280=2BNP52|270=1.31001|272=20190307|273=15:20:28.305|9122=15:20:28.301|290=4|279=1|269=1|278=o-47005822239596703-1|280=2BNP51|270=1.31016|272=20190307|273=15:20:28.305|9122=15:20:28.301|290=0|279=1|269=1|278=o-47005822239596703-2|280=2BNP52|270=1.31019|272=20190307|273=15:20:28.305|9122=15:20:28.301|290=1|279=0|269=1|278=o-47005822239596703-6|280=2BNP53|270=1.31024|271=10000000|15=GBP|272=20190307|273=15:20:28.305|9122=15:20:28.301|276=A|282=QPU08|290=5|279=2|269=1|280=9MS0a1|10=078|
8=FIX.4.4|9=0736|35=X|49=LFX|56=MKT.UAT.QPU600|34=47|52=20190307-15:20:29.233|262=MDReqID_1|55=GBP/USD|64=20190311|268=6|279=1|269=0|278=b-47005823043129657-5|280=7COBA0B1|270=1.31|272=20190307|273=15:20:29.125|9122=15:20:29.124|290=4|279=1|269=0|278=b-47005823043129657-9|280=7COBA0B2|270=1.30998|272=20190307|273=15:20:29.125|9122=15:20:29.124|290=8|279=0|269=0|278=b-47005823043129657-10|280=576|270=1.30997|271=4000000|272=20190307|273=15:20:28.205|9122=15:20:23.735|276=A|282=QPU90|290=9|279=2|269=0|280=7COBA0B3|279=1|269=1|278=o-47005823043129657-8|280=7COBA0O1|270=1.31026|272=20190307|273=15:20:29.125|9122=15:20:29.124|290=7|279=1|269=1|278=o-47005823043129657-10|280=7COBA0O2|270=1.31028|272=20190307|273=15:20:29.125|9122=15:20:29.124|290=9|10=030|
8=FIX.4.4|9=0279|35=X|49=LFX|56=MKT.UAT.QPU600|34=48|52=20190307-15:20:29.433|262=MDReqID_1|55=GBP/USD|64=20190311|268=2|279=0|269=1|278=o-47005823243174530-7|280=9MS0a1|270=1.31024|271=1000000|15=GBP|272=20190307|273=15:20:29.332|9122=15:20:29.330|276=A|282=QPU47|290=6|279=2|269=1|280=7COBA0O2|10=029|
8=FIX.4.4|9=0624|35=X|49=LFX|56=MKT.UAT.QPU600|34=49|52=20190307-15:20:29.633|262=MDReqID_1|55=GBP/USD|64=20190311|268=4|279=1|269=0|278=b-47005823443197337-1|280=1GBP/USD.1M@BAR.7.RFQ|270=1.31005|272=20190307|273=15:20:29.582|9122=15:20:29.089|290=0|279=1|269=0|278=b-47005823443197337-3|280=1GBP/USD.5M@BAR.7.RFQ|270=1.31003|272=20190307|273=15:20:29.582|9122=15:20:29.089|290=2|279=1|269=1|278=o-47005823443197337-1|280=1GBP/USD.1M@BAR.7.RFQ|270=1.31015|272=20190307|273=15:20:29.582|9122=15:20:29.089|290=0|279=1|269=1|278=o-47005823443197337-3|280=1GBP/USD.5M@BAR.7.RFQ|270=1.31017|272=20190307|273=15:20:29.582|9122=15:20:29.089|290=2|10=088|
8=FIX.4.4|9=0740|35=X|49=LFX|56=MKT.UAT.QPU600|34=50|52=20190307-15:20:30.430|262=MDReqID_1|55=GBP/USD|64=20190311|268=6|279=1|269=0|278=b-47005824240457902-1|280=2BNP51|270=1.31007|272=20190307|273=15:20:30.303|9122=15:20:30.301|290=0|279=1|269=0|278=b-47005824240457902-3|280=2BNP52|270=1.31004|272=20190307|273=15:20:30.303|9122=15:20:30.301|290=2|279=1|269=1|278=o-47005824240457902-6|280=2BNP51|270=1.31023|272=20190307|273=15:20:30.303|9122=15:20:30.301|290=5|279=1|269=1|278=o-47005824240457902-9|280=2BNP52|270=1.31026|272=20190307|273=15:20:30.303|9122=15:20:30.301|290=8|279=0|269=1|278=o-47005824240457902-10|280=7COBA0O2|270=1.31028|271=3000000|15=GBP|272=20190307|273=15:20:29.125|9122=15:20:29.124|276=A|282=QPU17|290=9|279=2|269=1|280=2BNP53|10=077|
8=FIX.4.4|9=0339|35=X|49=LFX|56=MKT.UAT.QPU600|34=51|52=20190307-15:20:30.433|262=MDReqID_1|55=GBP/USD|64=20190311|268=2|279=1|269=1|278=o-47005824243437553-9|280=7COBA0O1|270=1.31027|272=20190307|273=15:20:30.259|9122=15:20:30.258|290=8|279=1|269=1|278=o-47005824243437553-10|280=7COBA0O2|270=1.31029|272=20190307|273=15:20:30.259|9122=15:20:30.258|290=9|10=110|
8=FIX.4.4|9=0589|35=X|49=LFX|56=MKT.UAT.QPU600|34=52|52=20190307-15:20:30.433|262=MDReqID_1|55=GBP/USD|64=20190311|268=6|279=0|269=1|278=o-47005824243485954-5|280=5141|270=1.31026|271=4000000|272=20190307|273=15:20:30.256|9122=15:20:30.220|276=A|282=QPU90|290=4|279=0|269=1|278=o-47005824243485954-7|280=5232|270=1.31027|271=4000000|272=20190307|273=15:20:30.256|9122=15:20:30.220|276=A|282=QPU90|290=6|279=0|269=1|278=o-47005824243485954-9|280=5277|270=1.31028|271=4000000|272=20190307|273=15:20:30.256|9122=15:20:30.220|276=A|282=QPU90|290=8|279=2|269=1|280=521|279=2|269=1|280=5145|279=2|269=1|280=5200|10=004|
8=FIX.4.4|9=0394|35=X|49=LFX|56=MKT.UAT.QPU600|34=53|52=20190307-15:20:30.433|262=MDReqID_1|55=GBP/USD|64=20190311|268=3|279=1|269=0|278=b-47005824243667238-7|280=9MS0b1|270=1.30999|272=20190307|273=15:20:30.278|9122=15:20:30.278|290=6|279=0|269=1|278=o-47005824243667238-10|280=7COBA0O3|270=1.3103|271=5000000|15=GBP|272=20190307|273=15:20:30.259|9122=15:20:30.258|276=A|282=QPU17|290=9|279=2|269=1|280=9MS0a1|10=123|
8=FIX.4.4|9=0627|35=X|49=LFX|56=MKT.UAT.QPU600|34=54|52=20190307-15:20:30.633|262=MDReqID_1|55=GBP/USD|64=20190311|268=5|279=1|269=0|278=b-47005824443570546-5|280=7COBA0B1|270=1.31001|272=20190307|273=15:20:30.627|9122=15:20:30.626|290=4|279=1|269=0|278=b-47005824443570546-8|280=7COBA0B2|270=1.30999|272=20190307|273=15:20:30.627|9122=15:20:30.626|290=7|279=0|269=0|278=b-47005824443570546-9|280=7COBA0B3|270=1.30999|271=5000000|15=GBP|272=20190307|273=15:20:30.627|9122=15:20:30.626|276=A|282=QPU17|290=8|279=2|269=0|280=576|279=1|269=1|278=o-47005824443570546-8|280=7COBA0O1|270=1.31028|272=20190307|273=15:20:30.627|9122=15:20:30.626|290=7|10=025|
8=FIX.4.4|9=0623|35=X|49=LFX|56=MKT.UAT.QPU600|34=55|52=20190307-15:20:31.233|262=MDReqID_1|55=GBP/USD|64=20190311|268=4|279=1|269=0|278=b-47005825043539853-2|280=1GBP/USD.1M@BAR.7.RFQ|270=1.31006|272=20190307|273=15:20:31.119|9122=15:20:31.084|290=1|279=1|269=0|278=b-47005825043539853-4|280=1GBP/USD.5M@BAR.7.RFQ|270=1.31004|272=20190307|273=15:20:31.133|9122=15:20:31.085|290=3|279=1|269=1|278=o-47005825043539853-1|280=1GBP/USD.1M@BAR.7.RFQ|270=1.3102|272=20190307|273=15:20:31.119|9122=15:20:31.084|290=0|279=1|269=1|278=o-47005825043539853-2|280=1GBP/USD.5M@BAR.7.RFQ|270=1.31022|272=20190307|273=15:20:31.133|9122=15:20:31.085|290=1|10=183|
8=FIX.4.4|9=0514|35=X|49=LFX|56=MKT.UAT.QPU600|34=56|52=20190307-15:20:31.634|262=MDReqID_1|55=GBP/USD|64=20190311|268=4|279=1|269=0|278=b-47005825443854340-10|280=7COBA0B3|270=1.30998|272=20190307|273=15:20:31.628|9122=15:20:31.627|290=9|279=1|269=1|278=o-47005825443854340-9|280=7COBA0O2|270=1.3103|272=20190307|273=15:20:31.628|9122=15:20:31.627|290=8|279=0|269=1|278=o-47005825443854340-10|280=9MS0a1|270=1.31031|271=1000000|15=GBP|272=20190307|273=15:20:30.278|9122=15:20:30.278|276=A|282=QPU47|290=9|279=2|269=1|280=7COBA0O3|10=173|
8=FIX.4.4|9=0429|35=X|49=LFX|56=MKT.UAT.QPU600|34=57|52=20190307-15:20:32.034|262=MDReqID_1|55=GBP/USD|64=20190311|268=4|279=0|269=0|278=b-47005825844013367-8|280=5257|270=1.30999|271=4000000|272=20190307|273=15:20:31.980|9122=15:20:31.945|276=A|282=QPU90|290=7|279=0|269=0|278=b-47005825844013367-10|280=5169|270=1.30998|271=4000000|272=20190307|273=15:20:31.980|9122=15:20:31.945|276=A|282=QPU90|290=9|279=2|269=0|280=5110|279=2|269=0|280=5181|10=191|
8=FIX.4.4|9=0569|35=X|49=LFX|56=MKT.UAT.QPU600|34=58|52=20190307-15:20:32.234|262=MDReqID_1|55=GBP/USD|64=20190311|268=4|279=1|269=0|278=b-47005826043922005-5|280=7COBA0B1|270=1.31002|272=20190307|273=15:20:32.193|9122=15:20:32.192|290=4|279=1|269=0|278=b-47005826043922005-6|280=7COBA0B2|270=1.31001|272=20190307|273=15:20:32.193|9122=15:20:32.192|290=5|279=1|269=0|278=b-47005826043922005-7|280=7COBA0B3|270=1.31|272=20190307|273=15:20:32.193|9122=15:20:32.192|290=6|279=1|269=1|278=o-47005826043922005-8|280=7COBA0O1|270=1.31029|272=20190307|273=15:20:32.193|9122=15:20:32.192|290=7|10=145|
8=FIX.4.4|9=0612|35=X|49=LFX|56=MKT.UAT.QPU600|34=59|52=20190307-15:20:32.234|262=MDReqID_1|55=GBP/USD|64=20190311|268=6|279=0|269=1|278=o-47005826044025271-8|280=5151|270=1.31031|271=4000000|272=20190307|273=15:20:32.040|9122=15:20:32.005|276=A|282=QPU90|290=7|279=0|269=1|278=o-47005826044025271-9|280=7COBA0O3|270=1.31031|271=5000000|15=GBP|272=20190307|273=15:20:32.193|9122=15:20:32.192|276=A|282=QPU17|290=8|279=0|269=1|278=o-47005826044025271-10|280=2BNP53|270=1.31032|271=10000000|15=GBP|272=20190307|273=15:20:30.303|9122=15:20:30.301|276=A|282=QPU08|290=9|279=2|269=1|280=5141|279=2|269=1|280=5232|279=2|269=1|280=5277|10=046|
8=FIX.4.4|9=0383|35=X|49=LFX|56=MKT.UAT.QPU600|34=60|52=20190307-15:20:32.434|262=MDReqID_1|55=GBP/USD|64=20190311|268=3|279=1|269=0|278=b-47005826243929180-6|280=9MS0b1|270=1.31002|272=20190307|273=15:20:32.272|9122=15:20:32.262|290=5|279=0|269=1|278=o-47005826243929180-10|280=523|270=1.31032|271=4000000|272=20190307|273=15:20:32.040|9122=15:20:32.005|276=A|282=QPU90|290=9|279=2|269=1|280=9MS0a1|10=148|
8=FIX.4.4|9=0806|35=X|49=LFX|56=MKT.UAT.QPU600|34=61|52=20190307-15:20:32.634|262=MDReqID_1|55=GBP/USD|64=20190311|268=6|279=1|269=0|278=b-47005826443909728-5|280=7COBA0B1|270=1.31004|272=20190307|273=15:20:32.630|9122=15:20:32.629|290=4|279=1|269=0|278=b-47005826443909728-7|280=7COBA0B2|270=1.31002|272=20190307|273=15:20:32.630|9122=15:20:32.629|290=6|279=1|269=0|278=b-47005826443909728-8|280=7COBA0B3|270=1.31001|272=20190307|273=15:20:32.630|9122=15:20:32.629|290=7|279=1|269=1|278=o-47005826443909728-5|280=7COBA0O1|270=1.3103|272=20190307|273=15:20:32.630|9122=15:20:32.629|290=4|279=1|269=1|278=o-47005826443909728-7|280=7COBA0O2|270=1.31031|272=20190307|273=15:20:32.630|9122=15:20:32.629|290=6|279=1|269=1|278=o-47005826443909728-10|280=7COBA0O3|270=1.31032|272=20190307|273=15:20:32.630|9122=15:20:32.629|290=9|10=230|
8=FIX.4.4|9=0364|35=X|49=LFX|56=MKT.UAT.QPU600|34=62|52=20190307-15:20:32.834|262=MDReqID_1|55=GBP/USD|64=20190311|268=2|279=1|269=1|278=o-47005826643958723-2|280=1GBP/USD.1M@BAR.7.RFQ|270=1.31025|272=20190307|273=15:20:32.765|9122=15:20:32.111|290=1|279=1|269=1|278=o-47005826643958723-4|280=1GBP/USD.5M@BAR.7.RFQ|270=1.31027|272=20190307|273=15:20:32.765|9122=15:20:32.111|290=3|10=013|
8=FIX.4.4|9=0505|35=X|49=LFX|56=MKT.UAT.QPU600|34=63|52=20190307-15:20:33.234|262=MDReqID_1|55=GBP/USD|64=20190311|268=4|279=1|269=1|278=o-47005827044339009-6|280=7COBA0O1|270=1.31031|272=20190307|273=15:20:33.186|9122=15:20:33.185|290=5|279=0|269=1|278=o-47005827044339009-9|280=5223|270=1.31033|271=4000000|272=20190307|273=15:20:32.040|9122=15:20:32.005|276=A|282=QPU90|290=8|279=1|269=1|278=o-47005827044339009-10|280=7COBA0O2|270=1.31033|272=20190307|273=15:20:33.186|9122=15:20:33.185|290=9|279=2|269=1|280=7COBA0O3|10=084|
8=FIX.4.4|9=0670|35=X|49=LFX|56=MKT.UAT.QPU600|34=64|52=20190307-15:20:33.434|262=MDReqID_1|55=GBP/USD|64=20190311|268=6|279=1|269=0|278=b-47005827244267106-1|280=5257|270=1.31009|272=20190307|273=15:20:33.320|9122=15:20:33.285|290=0|279=1|269=0|278=b-47005827244267106-2|280=5169|270=1.31008|272=20190307|273=15:20:33.320|9122=15:20:33.285|290=1|279=0|269=0|278=b-47005827244267106-4|280=5203|270=1.31007|271=4000000|272=20190307|273=15:20:33.320|9122=15:20:33.285|276=A|282=QPU90|290=3|279=2|269=0|280=7COBA0B3|279=0|269=1|278=o-47005827244267106-10|280=7COBA0O3|270=1.31033|271=5000000|15=GBP|272=20190307|273=15:20:33.186|9122=15:20:33.185|276=A|282=QPU17|290=9|279=2|269=1|280=5223|10=051|
8=FIX.4.4|9=0797|35=X|49=LFX|56=MKT.UAT.QPU600|34=65|52=20190307-15:20:33.834|262=MDReqID_1|55=GBP/USD|64=20190311|268=7|279=1|269=0|278=b-47005827644367874-6|280=7COBA0B1|270=1.31005|272=20190307|273=15:20:33.633|9122=15:20:33.632|290=5|279=1|269=0|278=b-47005827644367874-9|280=7COBA0B2|270=1.31003|272=20190307|273=15:20:33.634|9122=15:20:33.632|290=8|279=1|269=1|278=o-47005827644367874-8|280=7COBA0O1|270=1.31032|272=20190307|273=15:20:33.634|9122=15:20:33.632|290=7|279=0|269=1|278=o-47005827644367874-9|280=5223|270=1.31033|271=4000000|272=20190307|273=15:20:33.320|9122=15:20:32.005|276=A|282=QPU90|290=8|279=0|269=1|278=o-47005827644367874-10|280=9MS0a1|270=1.31034|271=1000000|15=GBP|272=20190307|273=15:20:32.272|9122=15:20:32.262|276=A|282=QPU47|290=9|279=2|269=1|280=7COBA0O2|279=2|269=1|280=7COBA0O3|10=119|
8=FIX.4.4|9=0602|35=X|49=LFX|56=MKT.UAT.QPU600|34=66|52=20190307-15:20:33.834|262=MDReqID_1|55=GBP/USD|64=20190311|268=6|279=0|269=0|278=b-47005827644449727-6|280=5170|270=1.31004|271=4000000|272=20190307|273=15:20:33.825|9122=15:20:33.790|276=A|282=QPU90|290=5|279=0|269=0|278=b-47005827644449727-8|280=5185|270=1.31003|271=4000000|272=20190307|273=15:20:33.825|9122=15:20:33.790|276=A|282=QPU90|290=7|279=0|269=0|278=b-47005827644449727-10|280=7COBA0B3|270=1.31002|271=5000000|15=GBP|272=20190307|273=15:20:33.634|9122=15:20:33.632|276=A|282=QPU17|290=9|279=2|269=0|280=5257|279=2|269=0|280=5169|279=2|269=0|280=5203|10=030|
8=FIX.4.4|9=0364|35=X|49=LFX|56=MKT.UAT.QPU600|34=67|52=20190307-15:20:34.434|262=MDReqID_1|55=GBP/USD|64=20190311|268=2|279=1|269=0|278=b-47005828244434669-1|280=1GBP/USD.1M@BAR.7.RFQ|270=1.31011|272=20190307|273=15:20:34.428|9122=15:20:34.101|290=0|279=1|269=0|278=b-47005828244434669-2|280=1GBP/USD.5M@BAR.7.RFQ|270=1.31009|272=20190307|273=15:20:34.428|9122=15:20:34.102|290=1|10=226|
8=FIX.4.4|9=0338|35=X|49=LFX|56=MKT.UAT.QPU600|34=68|52=20190307-15:20:34.634|262=MDReqID_1|55=GBP/USD|64=20190311|268=2|279=1|269=0|278=b-47005828444543937-7|280=7COBA0B2|270=1.31004|272=20190307|273=15:20:34.632|9122=15:20:34.632|290=6|279=1|269=0|278=b-47005828444543937-9|280=7COBA0B3|270=1.31003|272=20190307|273=15:20:34.632|9122=15:20:34.632|290=8|10=034|
8=FIX.4.4|9=0729|35=X|49=LFX|56=MKT.UAT.QPU600|34=69|52=20190307-15:20:35.032|262=MDReqID_1|55=GBP/USD|64=20190311|268=6|279=1|269=0|278=b-47005828842013564-8|280=2BNP51|270=1.31003|272=20190307|273=15:20:34.935|9122=15:20:34.901|290=7|279=0|269=0|278=b-47005828842013564-10|280=5191|270=1.31002|271=4000000|272=20190307|273=15:20:33.825|9122=15:20:33.790|276=A|282=QPU90|290=9|279=2|269=0|280=2BNP52|279=1|269=1|278=o-47005828842013564-1|280=2BNP51|270=1.31016|272=20190307|273=15:20:34.935|9122=15:20:34.901|290=0|279=1|269=1|278=o-47005828842013564-2|280=2BNP52|270=1.31019|272=20190307|273=15:20:34.935|9122=15:20:34.901|290=1|279=1|269=1|278=o-47005828842013564-4|280=2BNP53|270=1.31025|272=20190307|273=15:20:34.935|9122=15:20:34.901|290=3|10=041|
8=FIX.4.4|9=0976|35=X|49=LFX|56=MKT.UAT.QPU600|34=70|52=20190307-15:20:35.035|262=MDReqID_1|55=GBP/USD|64=20190311|268=9|279=1|269=0|278=b-47005828844917227-6|280=7COBA0B1|270=1.31003|272=20190307|273=15:20:34.951|9122=15:20:34.951|290=5|279=1|269=0|278=b-47005828844917227-9|280=7COBA0B2|270=1.31001|272=20190307|273=15:20:34.952|9122=15:20:34.951|290=8|279=0|269=0|278=b-47005828844917227-10|280=2BNP52|270=1.31|271=6000000|15=GBP|272=20190307|273=15:20:34.935|9122=15:20:34.901|276=A|282=QPU08|290=9|279=2|269=0|280=7COBA0B3|279=1|269=1|278=o-47005828844917227-6|280=7COBA0O1|270=1.31029|272=20190307|273=15:20:34.952|9122=15:20:34.951|290=5|279=0|269=1|278=o-47005828844917227-8|280=7COBA0O2|270=1.31031|271=3000000|15=GBP|272=20190307|273=15:20:34.952|9122=15:20:34.951|276=A|282=QPU17|290=7|279=0|269=1|278=o-47005828844917227-9|280=7COBA0O3|270=1.31031|271=5000000|15=GBP|272=20190307|273=15:20:34.952|9122=15:20:34.951|276=A|282=QPU17|290=8|279=2|269=1|280=5223|279=2|269=1|280=9MS0a1|10=153|
8=FIX.4.4|9=0991|35=X|49=LFX|56=MKT.UAT.QPU600|34=71|52=20190307-15:20:35.035|262=MDReqID_1|55=GBP/USD|64=20190311|268=10|279=0|269=0|278=b-47005828844966289-8|280=7COBA0B3|270=1.31|271=5000000|15=GBP|272=20190307|273=15:20:34.952|9122=15:20:34.951|276=A|282=QPU17|290=7|279=0|269=0|278=b-47005828844966289-9|280=5203|270=1.30999|271=4000000|272=20190307|273=15:20:35.000|9122=15:20:34.965|276=A|282=QPU90|290=8|279=0|269=0|278=b-47005828844966289-10|280=5169|270=1.30998|271=4000000|272=20190307|273=15:20:35.000|9122=15:20:34.965|276=A|282=QPU90|290=9|279=2|269=0|280=5185|279=2|269=0|280=5191|279=2|269=0|280=5170|279=0|269=1|278=o-47005828844966289-3|280=5223|270=1.31021|271=4000000|272=20190307|273=15:20:35.000|9122=15:20:34.855|276=A|282=QPU90|290=2|279=1|269=1|278=o-47005828844966289-4|280=523|270=1.31022|272=20190307|273=15:20:35.000|9122=15:20:34.855|290=3|279=1|269=1|278=o-47005828844966289-5|280=5151|270=1.31023|272=20190307|273=15:20:35.000|9122=15:20:34.855|290=4|279=2|269=1|280=7COBA0O3|10=244|
8=FIX.4.4|9=0395|35=X|49=LFX|56=MKT.UAT.QPU600|34=72|52=20190307-15:20:35.035|262=MDReqID_1|55=GBP/USD|64=20190311|268=3|279=1|269=0|278=b-47005828845009681-8|280=9MS0b1|270=1.30999|272=20190307|273=15:20:34.887|9122=15:20:34.885|290=7|279=0|269=1|278=o-47005828845009681-10|280=9MS0a1|270=1.31031|271=1000000|15=GBP|272=20190307|273=15:20:34.887|9122=15:20:34.885|276=A|282=QPU47|290=9|279=2|269=1|280=7COBA0O2|10=224|
8=FIX.4.4|9=0624|35=X|49=LFX|56=MKT.UAT.QPU600|34=73|52=20190307-15:20:35.235|262=MDReqID_1|55=GBP/USD|64=20190311|268=4|279=1|269=0|278=b-47005829045111291-1|280=1GBP/USD.1M@BAR.7.RFQ|270=1.31005|272=20190307|273=15:20:35.132|9122=15:20:35.082|290=0|279=1|269=0|278=b-47005829045111291-4|280=1GBP/USD.5M@BAR.7.RFQ|270=1.31003|272=20190307|273=15:20:35.154|9122=15:20:35.082|290=3|279=1|269=1|278=o-47005829045111291-1|280=1GBP/USD.1M@BAR.7.RFQ|270=1.31015|272=20190307|273=15:20:35.132|9122=15:20:35.082|290=0|279=1|269=1|278=o-47005829045111291-3|280=1GBP/USD.5M@BAR.7.RFQ|270=1.31017|272=20190307|273=15:20:35.154|9122=15:20:35.082|290=2|10=214|
8=FIX.4.4|9=1070|35=X|49=LFX|56=MKT.UAT.QPU600|34=74|52=20190307-15:20:35.235|262=MDReqID_1|55=GBP/USD|64=20190311|268=10|279=1|269=0|278=b-47005829045203271-4|280=7COBA0B1|270=1.31001|272=20190307|273=15:20:35.218|9122=15:20:35.217|290=3|279=1|269=0|278=b-47005829045203271-6|280=7COBA0B2|270=1.31|272=20190307|273=15:20:35.218|9122=15:20:35.217|290=5|279=0|269=0|278=b-47005829045203271-8|280=529|270=1.30999|271=4000000|272=20190307|273=15:20:35.060|9122=15:20:35.025|276=A|282=QPU90|290=7|279=1|269=0|278=b-47005829045203271-9|280=7COBA0B3|270=1.30999|272=20190307|273=15:20:35.218|9122=15:20:35.217|290=8|279=0|269=0|278=b-47005829045203271-10|280=5165|270=1.30998|271=4000000|272=20190307|273=15:20:35.060|9122=15:20:35.025|276=A|282=QPU90|290=9|279=2|269=0|280=5169|279=2|269=0|280=5203|279=1|269=1|278=o-47005829045203271-9|280=7COBA0O1|270=1.31026|272=20190307|273=15:20:35.218|9122=15:20:35.217|290=8|279=0|269=1|278=o-47005829045203271-10|280=7COBA0O2|270=1.31028|271=3000000|15=GBP|272=20190307|273=15:20:35.218|9122=15:20:35.217|276=A|282=QPU17|290=9|279=2|269=1|280=9MS0a1|10=221|
8=FIX.4.4|9=0395|35=X|49=LFX|56=MKT.UAT.QPU600|34=75|52=20190307-15:20:35.835|262=MDReqID_1|55=GBP/USD|64=20190311|268=3|279=1|269=0|278=b-47005829645290839-10|280=9MS0b1|270=1.30998|272=20190307|273=15:20:35.828|9122=15:20:35.826|290=9|279=0|269=1|278=o-47005829645290839-8|280=9MS0a1|270=1.31024|271=1000000|15=GBP|272=20190307|273=15:20:35.828|9122=15:20:35.826|276=A|282=QPU47|290=7|279=2|269=1|280=7COBA0O2|10=232|
8=FIX.4.4|9=0453|35=X|49=LFX|56=MKT.UAT.QPU600|34=76|52=20190307-15:20:36.035|262=MDReqID_1|55=GBP/USD|64=20190311|268=3|279=1|269=0|278=b-47005829845234300-5|280=7COBA0B1|270=1.31|272=20190307|273=15:20:35.954|9122=15:20:35.952|290=4|279=1|269=0|278=b-47005829845234300-9|280=7COBA0B2|270=1.30998|272=20190307|273=15:20:35.954|9122=15:20:35.952|290=8|279=1|269=0|278=b-47005829845234300-10|280=7COBA0B3|270=1.30998|272=20190307|273=15:20:35.954|9122=15:20:35.952|290=9|10=128|
8=FIX.4.4|9=0271|35=X|49=LFX|56=MKT.UAT.QPU600|34=77|52=20190307-15:20:39.236|262=MDReqID_1|55=GBP/USD|64=20190311|268=2|279=0|269=0|278=b-47005833046034835-10|280=5249|270=1.30997|271=4000000|272=20190307|273=15:20:35.060|9122=15:20:35.025|276=A|282=QPU90|290=9|279=2|269=0|280=7COBA0B3|10=248|
8=FIX.4.4|9=1097|35=X|49=LFX|56=MKT.UAT.QPU600|34=78|52=20190307-15:20:39.640|262=MDReqID_1|55=GBP/USD|64=20190311|268=12|279=0|269=0|278=b-47005833450144753-6|280=546|270=1.30999|271=4000000|272=20190307|273=15:20:39.555|9122=15:20:39.425|276=A|282=QPU90|290=5|279=0|269=0|278=b-47005833450144753-9|280=5122|270=1.30998|271=4000000|272=20190307|273=15:20:39.555|9122=15:20:39.425|276=A|282=QPU90|290=8|279=0|269=0|278=b-47005833450144753-10|280=7COBA0B3|270=1.30997|271=5000000|15=GBP|272=20190307|273=15:20:39.153|9122=15:20:39.152|276=A|282=QPU17|290=9|279=2|269=0|280=5165|279=2|269=0|280=5249|279=2|269=0|280=529|279=0|269=1|278=o-47005833450144753-8|280=586|270=1.31026|271=4000000|272=20190307|273=15:20:39.555|9122=15:20:39.520|276=A|282=QPU90|290=7|279=0|269=1|278=o-47005833450144753-9|280=5100|270=1.31027|271=4000000|272=20190307|273=15:20:39.555|9122=15:20:39.520|276=A|282=QPU90|290=8|279=0|269=1|278=o-47005833450144753-10|280=7COBA0O2|270=1.31028|271=3000000|15=GBP|272=20190307|273=15:20:39.153|9122=15:20:39.152|276=A|282=QPU17|290=9|279=2|269=1|280=5151|279=2|269=1|280=5223|279=2|269=1|280=523|10=013|
8=FIX.4.4|9=0389|35=X|49=LFX|56=MKT.UAT.QPU600|34=79|52=20190307-15:20:40.240|262=MDReqID_1|55=GBP/USD|64=20190311|268=3|279=1|269=0|278=b-47005834050299973-10|280=7COBA0B3|270=1.30998|272=20190307|273=15:20:40.152|9122=15:20:40.151|290=9|279=0|269=1|278=o-47005834050299973-10|280=5149|270=1.31028|271=4000000|272=20190307|273=15:20:39.555|9122=15:20:39.520|276=A|282=QPU90|290=9|279=2|269=1|280=7COBA0O2|10=246|
8=FIX.4.4|9=0623|35=X|49=LFX|56=MKT.UAT.QPU600|34=80|52=20190307-15:20:40.440|262=MDReqID_1|55=GBP/USD|64=20190311|268=4|279=1|269=0|278=b-47005834250287375-1|280=1GBP/USD.1M@BAR.7.RFQ|270=1.31006|272=20190307|273=15:20:40.384|9122=15:20:40.099|290=0|279=1|269=0|278=b-47005834250287375-2|280=1GBP/USD.5M@BAR.7.RFQ|270=1.31004|272=20190307|273=15:20:40.384|9122=15:20:40.100|290=1|279=1|269=1|278=o-47005834250287375-3|280=1GBP/USD.1M@BAR.7.RFQ|270=1.3102|272=20190307|273=15:20:40.384|9122=15:20:40.099|290=2|279=1|269=1|278=o-47005834250287375-4|280=1GBP/USD.5M@BAR.7.RFQ|270=1.31022|272=20190307|273=15:20:40.384|9122=15:20:40.100|290=3|10=191|
8=FIX.4.4|9=0442|35=X|49=LFX|56=MKT.UAT.QPU600|34=81|52=20190307-15:20:40.840|262=MDReqID_1|55=GBP/USD|64=20190311|268=3|279=1|269=1|278=o-47005834650400924-4|280=5149|270=1.31021|272=20190307|273=15:20:40.715|9122=15:20:40.680|290=3|279=1|269=1|278=o-47005834650400924-6|280=5100|270=1.31022|272=20190307|273=15:20:40.715|9122=15:20:40.680|290=5|279=1|269=1|278=o-47005834650400924-7|280=586|270=1.31023|272=20190307|273=15:20:40.715|9122=15:20:40.680|290=6|10=014|
8=FIX.4.4|9=0624|35=X|49=LFX|56=MKT.UAT.QPU600|34=82|52=20190307-15:20:41.241|262=MDReqID_1|55=GBP/USD|64=20190311|268=4|279=1|269=0|278=b-47005835050652205-1|280=1GBP/USD.1M@BAR.7.RFQ|270=1.31005|272=20190307|273=15:20:41.130|9122=15:20:41.083|290=0|279=1|269=0|278=b-47005835050652205-3|280=1GBP/USD.5M@BAR.7.RFQ|270=1.31003|272=20190307|273=15:20:41.132|9122=15:20:41.083|290=2|279=1|269=1|278=o-47005835050652205-1|280=1GBP/USD.1M@BAR.7.RFQ|270=1.31015|272=20190307|273=15:20:41.130|9122=15:20:41.083|290=0|279=1|269=1|278=o-47005835050652205-3|280=1GBP/USD.5M@BAR.7.RFQ|270=1.31017|272=20190307|273=15:20:41.132|9122=15:20:41.083|290=2|10=166|
8=FIX.4.4|9=0339|35=X|49=LFX|56=MKT.UAT.QPU600|34=83|52=20190307-15:20:41.441|262=MDReqID_1|55=GBP/USD|64=20190311|268=2|279=1|269=0|278=b-47005835250790651-7|280=7COBA0B2|270=1.30999|272=20190307|273=15:20:41.241|9122=15:20:41.241|290=6|279=1|269=1|278=o-47005835250790651-10|280=7COBA0O1|270=1.31027|272=20190307|273=15:20:41.241|9122=15:20:41.241|290=9|10=076|
8=FIX.4.4|9=0506|35=X|49=LFX|56=MKT.UAT.QPU600|34=84|52=20190307-15:20:42.441|262=MDReqID_1|55=GBP/USD|64=20190311|268=4|279=1|269=0|278=b-47005836251161696-9|280=7COBA0B2|270=1.30998|272=20190307|273=15:20:42.249|9122=15:20:42.248|290=8|279=0|269=0|278=b-47005836251161696-10|280=5184|270=1.30997|271=4000000|272=20190307|273=15:20:40.715|9122=15:20:39.425|276=A|282=QPU90|290=9|279=2|269=0|280=7COBA0B3|279=1|269=1|278=o-47005836251161696-10|280=7COBA0O1|270=1.31026|272=20190307|273=15:20:42.249|9122=15:20:42.248|290=9|10=163|
8=FIX.4.4|9=0774|35=X|49=LFX|56=MKT.UAT.QPU600|34=85|52=20190307-15:20:42.841|262=MDReqID_1|55=GBP/USD|64=20190311|268=8|279=0|269=0|278=b-47005836651258747-10|280=7COBA0B3|270=1.30997|271=5000000|15=GBP|272=20190307|273=15:20:42.249|9122=15:20:42.248|276=A|282=QPU17|290=9|279=2|269=0|280=5184|279=0|269=1|278=o-47005836651258747-8|280=559|270=1.31026|271=4000000|272=20190307|273=15:20:42.721|9122=15:20:42.685|276=A|282=QPU90|290=7|279=0|269=1|278=o-47005836651258747-9|280=5171|270=1.31027|271=4000000|272=20190307|273=15:20:42.721|9122=15:20:42.685|276=A|282=QPU90|290=8|279=0|269=1|278=o-47005836651258747-10|280=7COBA0O2|270=1.31028|271=3000000|15=GBP|272=20190307|273=15:20:42.249|9122=15:20:42.248|276=A|282=QPU17|290=9|279=2|269=1|280=586|279=2|269=1|280=5100|279=2|269=1|280=5149|10=193|
8=FIX.4.4|9=0384|35=X|49=LFX|56=MKT.UAT.QPU600|34=86|52=20190307-15:20:42.841|262=MDReqID_1|55=GBP/USD|64=20190311|268=3|279=1|269=0|278=b-47005836651280444-4|280=9MS0b1|270=1.31002|272=20190307|273=15:20:42.725|9122=15:20:42.706|290=3|279=0|269=1|278=o-47005836651280444-10|280=5189|270=1.31028|271=4000000|272=20190307|273=15:20:42.721|9122=15:20:42.685|276=A|282=QPU90|290=9|279=2|269=1|280=9MS0a1|10=246|
8=FIX.4.4|9=0623|35=X|49=LFX|56=MKT.UAT.QPU600|34=87|52=20190307-15:20:43.241|262=MDReqID_1|55=GBP/USD|64=20190311|268=4|279=1|269=0|278=b-47005837051434080-1|280=1GBP/USD.1M@BAR.7.RFQ|270=1.31006|272=20190307|273=15:20:43.119|9122=15:20:43.068|290=0|279=1|269=0|278=b-47005837051434080-2|280=1GBP/USD.5M@BAR.7.RFQ|270=1.31004|272=20190307|273=15:20:43.098|9122=15:20:43.068|290=1|279=1|269=1|278=o-47005837051434080-3|280=1GBP/USD.1M@BAR.7.RFQ|270=1.3102|272=20190307|273=15:20:43.119|9122=15:20:43.068|290=2|279=1|269=1|278=o-47005837051434080-4|280=1GBP/USD.5M@BAR.7.RFQ|270=1.31022|272=20190307|273=15:20:43.098|9122=15:20:43.068|290=3|10=194|
8=FIX.4.4|9=0515|35=X|49=LFX|56=MKT.UAT.QPU600|34=88|52=20190307-15:20:43.441|262=MDReqID_1|55=GBP/USD|64=20190311|268=4|279=1|269=0|278=b-47005837251504427-10|280=7COBA0B3|270=1.30998|272=20190307|273=15:20:43.246|9122=15:20:43.245|290=9|279=1|269=1|278=o-47005837251504427-8|280=7COBA0O1|270=1.31027|272=20190307|273=15:20:43.246|9122=15:20:43.245|290=7|279=0|269=1|278=o-47005837251504427-10|280=9MS0a1|270=1.31028|271=1000000|15=GBP|272=20190307|273=15:20:42.725|9122=15:20:42.706|276=A|282=QPU47|290=9|279=2|269=1|280=7COBA0O2|10=223|
8=FIX.4.4|9=0335|35=X|49=LFX|56=MKT.UAT.QPU600|34=89|52=20190307-15:20:44.041|262=MDReqID_1|55=GBP/USD|64=20190311|268=2|279=1|269=0|278=b-47005837851576859-10|280=9MS0b1|270=1.30998|272=20190307|273=15:20:43.980|9122=15:20:43.972|290=9|279=1|269=1|278=o-47005837851576859-5|280=9MS0a1|270=1.31024|272=20190307|273=15:20:43.980|9122=15:20:43.972|290=4|10=236|
8=FIX.4.4|9=0338|35=X|49=LFX|56=MKT.UAT.QPU600|34=90|52=20190307-15:20:44.642|262=MDReqID_1|55=GBP/USD|64=20190311|268=2|279=1|269=0|278=b-47005838451922139-4|280=7COBA0B1|270=1.31001|272=20190307|273=15:20:44.583|9122=15:20:44.582|290=3|279=1|269=0|278=b-47005838451922139-7|280=7COBA0B2|270=1.30999|272=20190307|273=15:20:44.583|9122=15:20:44.582|290=6|10=047|
8=FIX.4.4|9=0395|35=X|49=LFX|56=MKT.UAT.QPU600|34=91|52=20190307-15:20:45.242|262=MDReqID_1|55=GBP/USD|64=20190311|268=3|279=1|269=0|278=b-47005839051970205-4|280=9MS0b1|270=1.31003|272=20190307|273=15:20:45.047|9122=15:20:45.046|290=3|279=0|269=1|278=o-47005839051970205-10|280=7COBA0O2|270=1.31029|271=3000000|15=GBP|272=20190307|273=15:20:44.583|9122=15:20:44.582|276=A|282=QPU17|290=9|279=2|269=1|280=9MS0a1|10=151|
8=FIX.4.4|9=1408|35=X|49=LFX|56=MKT.UAT.QPU600|34=92|52=20190307-15:20:45.242|262=MDReqID_1|55=GBP/USD|64=20190311|268=13|279=1|269=0|278=b-47005839052026694-5|280=7COBA0B1|270=1.31002|272=20190307|273=15:20:45.044|9122=15:20:45.043|290=4|279=1|269=0|278=b-47005839052026694-7|280=7COBA0B2|270=1.31|272=20190307|273=15:20:45.044|9122=15:20:45.043|290=6|279=1|269=0|278=b-47005839052026694-8|280=7COBA0B3|270=1.30999|272=20190307|273=15:20:45.044|9122=15:20:45.043|290=7|279=0|269=0|278=b-47005839052026694-9|280=5132|270=1.30999|271=4000000|272=20190307|273=15:20:45.145|9122=15:20:45.110|276=A|282=QPU90|290=8|279=0|269=0|278=b-47005839052026694-10|280=5137|270=1.30998|271=4000000|272=20190307|273=15:20:45.145|9122=15:20:45.110|276=A|282=QPU90|290=9|279=2|269=0|280=5122|279=2|269=0|280=546|279=1|269=1|278=o-47005839052026694-4|280=5189|270=1.31021|272=20190307|273=15:20:45.145|9122=15:20:45.015|290=3|279=1|269=1|278=o-47005839052026694-6|280=5171|270=1.31022|272=20190307|273=15:20:45.145|9122=15:20:45.015|290=5|279=1|269=1|278=o-47005839052026694-7|280=559|270=1.31023|272=20190307|273=15:20:45.145|9122=15:20:45.015|290=6|279=1|269=1|278=o-47005839052026694-9|280=7COBA0O1|270=1.31028|272=20190307|273=15:20:45.044|9122=15:20:45.043|290=8|279=0|269=1|278=o-47005839052026694-10|280=9MS0a1|270=1.31029|271=1000000|15=GBP|272=20190307|273=15:20:45.047|9122=15:20:45.046|276=A|282=QPU47|290=9|279=2|269=1|280=7COBA0O2|10=132|
8=FIX.4.4|9=0383|35=X|49=LFX|56=MKT.UAT.QPU600|34=93|52=20190307-15:20:45.842|262=MDReqID_1|55=GBP/USD|64=20190311|268=3|279=0|269=0|278=b-47005839652324421-10|280=543|270=1.30997|271=4000000|272=20190307|273=15:20:45.145|9122=15:20:45.110|276=A|282=QPU90|290=9|279=2|269=0|280=9MS0b1|279=1|269=1|278=o-47005839652324421-8|280=9MS0a1|270=1.31023|272=20190307|273=15:20:45.790|9122=15:20:45.789|290=7|10=216|
8=FIX.4.4|9=0338|35=X|49=LFX|56=MKT.UAT.QPU600|34=94|52=20190307-15:20:46.242|262=MDReqID_1|55=GBP/USD|64=20190311|268=2|279=1|269=0|278=b-47005840052383649-4|280=7COBA0B1|270=1.31001|272=20190307|273=15:20:46.046|9122=15:20:46.045|290=3|279=1|269=0|278=b-47005840052383649-7|280=7COBA0B2|270=1.30999|272=20190307|273=15:20:46.046|9122=15:20:46.045|290=6|10=027|
8=FIX.4.4|9=0624|35=X|49=LFX|56=MKT.UAT.QPU600|34=95|52=20190307-15:20:46.442|262=MDReqID_1|55=GBP/USD|64=20190311|268=4|279=1|269=0|278=b-47005840252396611-1|280=1GBP/USD.1M@BAR.7.RFQ|270=1.31005|272=20190307|273=15:20:46.338|9122=15:20:46.102|290=0|279=1|269=0|278=b-47005840252396611-3|280=1GBP/USD.5M@BAR.7.RFQ|270=1.31003|272=20190307|273=15:20:46.338|9122=15:20:46.102|290=2|279=1|269=1|278=o-47005840252396611-1|280=1GBP/USD.1M@BAR.7.RFQ|270=1.31015|272=20190307|273=15:20:46.338|9122=15:20:46.102|290=0|279=1|269=1|278=o-47005840252396611-3|280=1GBP/USD.5M@BAR.7.RFQ|270=1.31017|272=20190307|273=15:20:46.338|9122=15:20:46.102|290=2|10=246|
8=FIX.4.4|9=0389|35=X|49=LFX|56=MKT.UAT.QPU600|34=96|52=20190307-15:20:47.643|262=MDReqID_1|55=GBP/USD|64=20190311|268=3|279=0|269=0|278=b-47005841453049643-9|280=9MS0b1|270=1.30999|271=1000000|15=GBP|272=20190307|273=15:20:47.472|9122=15:20:47.471|276=A|282=QPU47|290=8|279=2|269=0|280=543|279=1|269=1|278=o-47005841453049643-9|280=9MS0a1|270=1.31025|272=20190307|273=15:20:47.472|9122=15:20:47.471|290=8|10=069|
8=FIX.4.4|9=0340|35=X|49=LFX|56=MKT.UAT.QPU600|34=97|52=20190307-15:20:50.246|262=MDReqID_1|55=GBP/USD|64=20190311|268=2|279=1|269=0|278=b-47005844055727326-10|280=7COBA0B3|270=1.30998|272=20190307|273=15:20:50.085|9122=15:20:50.085|290=9|279=1|269=1|278=o-47005844055727326-10|280=7COBA0O1|270=1.31027|272=20190307|273=15:20:50.085|9122=15:20:50.085|290=9|10=149|
8=FIX.4.4|9=0335|35=X|49=LFX|56=MKT.UAT.QPU600|34=98|52=20190307-15:20:51.444|262=MDReqID_1|55=GBP/USD|64=20190311|268=2|279=1|269=0|278=b-47005845253962622-6|280=7COBA0B2|270=1.31|272=20190307|273=15:20:51.286|9122=15:20:51.283|290=5|279=1|269=0|278=b-47005845253962622-9|280=7COBA0B3|270=1.30999|272=20190307|273=15:20:51.286|9122=15:20:51.283|290=8|10=157|
8=FIX.4.4|9=0339|35=X|49=LFX|56=MKT.UAT.QPU600|34=99|52=20190307-15:20:52.444|262=MDReqID_1|55=GBP/USD|64=20190311|268=2|279=1|269=0|278=b-47005846254302927-8|280=7COBA0B2|270=1.30999|272=20190307|273=15:20:52.279|9122=15:20:52.278|290=7|279=1|269=0|278=b-47005846254302927-10|280=7COBA0B3|270=1.30998|272=20190307|273=15:20:52.279|9122=15:20:52.278|290=9|10=133|
8=FIX.4.4|9=0336|35=X|49=LFX|56=MKT.UAT.QPU600|34=100|52=20190307-15:20:54.245|262=MDReqID_1|55=GBP/USD|64=20190311|268=2|279=1|269=0|278=b-47005848054891093-5|280=7COBA0B1|270=1.31|272=20190307|273=15:20:54.173|9122=15:20:54.167|290=4|279=1|269=0|278=b-47005848054891093-9|280=7COBA0B2|270=1.30998|272=20190307|273=15:20:54.173|9122=15:20:54.167|290=8|10=201|
8=FIX.4.4|9=0223|35=X|49=LFX|56=MKT.UAT.QPU600|34=101|52=20190307-15:20:56.446|262=MDReqID_1|55=GBP/USD|64=20190311|268=1|279=1|269=1|278=o-47005850255642315-10|280=7COBA0O1|270=1.31026|272=20190307|273=15:20:56.262|9122=15:20:56.253|290=9|10=224|
8=FIX.4.4|9=0271|35=X|49=LFX|56=MKT.UAT.QPU600|34=102|52=20190307-15:21:00.646|262=MDReqID_1|55=GBP/USD|64=20190311|268=2|279=0|269=0|278=b-47005854456592037-10|280=543|270=1.30997|271=4000000|272=20190307|273=15:20:45.145|9122=15:20:45.110|276=A|282=QPU90|290=9|279=2|269=0|280=7COBA0B3|10=235|
8=FIX.4.4|9=0611|35=X|49=LFX|56=MKT.UAT.QPU600|34=103|52=20190307-15:21:01.047|262=MDReqID_1|55=GBP/USD|64=20190311|268=6|279=0|269=0|278=b-47005854856936126-8|280=7COBA0B3|270=1.30997|271=5000000|15=GBP|272=20190307|273=15:21:00.578|9122=15:21:00.577|276=A|282=QPU17|290=7|279=0|269=0|278=b-47005854856936126-9|280=2BNP53|270=1.30996|271=10000000|15=GBP|272=20190307|273=15:20:34.935|9122=15:20:34.901|276=A|282=QPU08|290=8|279=0|269=0|278=b-47005854856936126-10|280=582|270=1.30994|271=4000000|272=20190307|273=15:21:00.971|9122=15:21:00.935|276=A|282=QPU90|290=9|279=2|269=0|280=5132|279=2|269=0|280=543|279=2|269=0|280=5137|10=095|
8=FIX.4.4|9=0335|35=X|49=LFX|56=MKT.UAT.QPU600|34=104|52=20190307-15:21:01.047|262=MDReqID_1|55=GBP/USD|64=20190311|268=2|279=1|269=0|278=b-47005854857155312-8|280=9MS0b1|270=1.30997|272=20190307|273=15:21:00.973|9122=15:21:00.968|290=7|279=1|269=1|278=o-47005854857155312-8|280=9MS0a1|270=1.31023|272=20190307|273=15:21:00.973|9122=15:21:00.968|290=7|10=187|
8=FIX.4.4|9=0574|35=X|49=LFX|56=MKT.UAT.QPU600|34=105|52=20190307-15:21:01.047|262=MDReqID_1|55=GBP/USD|64=20190311|268=4|279=1|269=0|278=b-47005854857242957-5|280=7COBA0B1|270=1.30999|272=20190307|273=15:21:01.036|9122=15:21:01.030|290=4|279=1|269=0|278=b-47005854857242957-7|280=7COBA0B2|270=1.30997|272=20190307|273=15:21:01.036|9122=15:21:01.030|290=6|279=1|269=0|278=b-47005854857242957-9|280=7COBA0B3|270=1.30996|272=20190307|273=15:21:01.036|9122=15:21:01.030|290=8|279=1|269=1|278=o-47005854857242957-10|280=7COBA0O1|270=1.31025|272=20190307|273=15:21:01.036|9122=15:21:01.030|290=9|10=208|
8=FIX.4.4|9=0625|35=X|49=LFX|56=MKT.UAT.QPU600|34=106|52=20190307-15:21:01.247|262=MDReqID_1|55=GBP/USD|64=20190311|268=4|279=1|269=0|278=b-47005855056968498-8|280=1GBP/USD.1M@BAR.7.RFQ|270=1.30996|272=20190307|273=15:21:01.218|9122=15:21:01.106|290=7|279=1|269=0|278=b-47005855056968498-10|280=1GBP/USD.5M@BAR.7.RFQ|270=1.30994|272=20190307|273=15:21:01.229|9122=15:21:01.106|290=9|279=1|269=1|278=o-47005855056968498-1|280=1GBP/USD.1M@BAR.7.RFQ|270=1.3101|272=20190307|273=15:21:01.218|9122=15:21:01.106|290=0|279=1|269=1|278=o-47005855056968498-2|280=1GBP/USD.5M@BAR.7.RFQ|270=1.31012|272=20190307|273=15:21:01.229|9122=15:21:01.106|290=1|10=118|
8=FIX.4.4|9=0749|35=X|49=LFX|56=MKT.UAT.QPU600|34=107|52=20190307-15:21:01.247|262=MDReqID_1|55=GBP/USD|64=20190311|268=8|279=0|269=0|278=b-47005855057006831-9|280=540|270=1.30994|271=4000000|272=20190307|273=15:21:01.106|9122=15:21:01.070|276=A|282=QPU90|290=8|279=2|269=0|280=582|279=0|269=1|278=o-47005855057006831-5|280=5132|270=1.31021|271=4000000|272=20190307|273=15:21:01.106|9122=15:21:01.040|276=A|282=QPU90|290=4|279=0|269=1|278=o-47005855057006831-6|280=5137|270=1.31022|271=4000000|272=20190307|273=15:21:01.106|9122=15:21:01.040|276=A|282=QPU90|290=5|279=0|269=1|278=o-47005855057006831-8|280=543|270=1.31023|271=4000000|272=20190307|273=15:21:01.106|9122=15:21:01.040|276=A|282=QPU90|290=7|279=2|269=1|280=5189|279=2|269=1|280=559|279=2|269=1|280=5171|10=045|
8=FIX.4.4|9=0267|35=X|49=LFX|56=MKT.UAT.QPU600|34=108|52=20190307-15:21:02.047|262=MDReqID_1|55=GBP/USD|64=20190311|268=2|279=0|269=0|278=b-47005855857082357-10|280=5199|270=1.30989|271=4000000|272=20190307|273=15:21:01.970|9122=15:21:01.935|276=A|282=QPU90|290=9|279=2|269=0|280=540|10=228|
8=FIX.4.4|9=0456|35=X|49=LFX|56=MKT.UAT.QPU600|34=109|52=20190307-15:21:02.247|262=MDReqID_1|55=GBP/USD|64=20190311|268=3|279=1|269=0|278=b-47005856057186835-3|280=7COBA0B1|270=1.30998|272=20190307|273=15:21:02.053|9122=15:21:02.050|290=2|279=1|269=0|278=b-47005856057186835-7|280=7COBA0B2|270=1.30996|272=20190307|273=15:21:02.053|9122=15:21:02.050|290=6|279=1|269=0|278=b-47005856057186835-8|280=7COBA0B3|270=1.30995|272=20190307|273=15:21:02.053|9122=15:21:02.050|290=7|10=237|
8=FIX.4.4|9=0599|35=X|49=LFX|56=MKT.UAT.QPU600|34=110|52=20190307-15:21:02.847|262=MDReqID_1|55=GBP/USD|64=20190311|268=4|279=1|269=0|278=b-47005856657370201-4|280=7COBA0B1|270=1.30997|272=20190307|273=15:21:02.676|9122=15:21:02.676|290=3|279=1|269=1|278=o-47005856657370201-1|280=1GBP/USD.1M@BAR.7.RFQ|270=1.31015|272=20190307|273=15:21:02.680|9122=15:21:02.113|290=0|279=1|269=1|278=o-47005856657370201-3|280=1GBP/USD.5M@BAR.7.RFQ|270=1.31017|272=20190307|273=15:21:02.680|9122=15:21:02.113|290=2|279=1|269=1|278=o-47005856657370201-9|280=7COBA0O1|270=1.31023|272=20190307|273=15:21:02.676|9122=15:21:02.676|290=8|10=129|
8=FIX.4.4|9=0456|35=X|49=LFX|56=MKT.UAT.QPU600|34=111|52=20190307-15:21:03.247|262=MDReqID_1|55=GBP/USD|64=20190311|268=3|279=1|269=0|278=b-47005857057538618-6|280=7COBA0B1|270=1.30996|272=20190307|273=15:21:03.051|9122=15:21:03.050|290=5|279=1|269=0|278=b-47005857057538618-7|280=7COBA0B2|270=1.30995|272=20190307|273=15:21:03.051|9122=15:21:03.050|290=6|279=1|269=0|278=b-47005857057538618-9|280=7COBA0B3|270=1.30994|272=20190307|273=15:21:03.051|9122=15:21:03.050|290=8|10=238|
8=FIX.4.4|9=0513|35=X|49=LFX|56=MKT.UAT.QPU600|34=112|52=20190307-15:21:04.648|262=MDReqID_1|55=GBP/USD|64=20190311|268=4|279=1|269=0|278=b-47005858457785805-4|280=7COBA0B1|270=1.30997|272=20190307|273=15:21:04.629|9122=15:21:04.628|290=3|279=1|269=1|278=o-47005858457785805-5|280=7COBA0O1|270=1.3102|272=20190307|273=15:21:04.629|9122=15:21:04.628|290=4|279=0|269=1|278=o-47005858457785805-8|280=7COBA0O2|270=1.31022|271=3000000|15=GBP|272=20190307|273=15:21:04.629|9122=15:21:04.628|276=A|282=QPU17|290=7|279=2|269=1|280=2BNP53|10=148|
8=FIX.4.4|9=0440|35=X|49=LFX|56=MKT.UAT.QPU600|34=113|52=20190307-15:21:05.048|262=MDReqID_1|55=GBP/USD|64=20190311|268=4|279=0|269=0|278=b-47005858857994116-10|280=515|270=1.30994|271=4000000|272=20190307|273=15:21:04.895|9122=15:21:04.860|276=A|282=QPU90|290=9|279=2|269=0|280=5199|279=0|269=1|278=o-47005858857994116-10|280=7COBA0O3|270=1.31023|271=5000000|15=GBP|272=20190307|273=15:21:04.629|9122=15:21:04.628|276=A|282=QPU17|290=9|279=2|269=1|280=543|10=127|
8=FIX.4.4|9=0267|35=X|49=LFX|56=MKT.UAT.QPU600|34=114|52=20190307-15:21:05.449|262=MDReqID_1|55=GBP/USD|64=20190311|268=2|279=0|269=0|278=b-47005859259480785-10|280=5256|270=1.30989|271=4000000|272=20190307|273=15:21:05.415|9122=15:21:05.380|276=A|282=QPU90|290=9|279=2|269=0|280=515|10=233|
8=FIX.4.4|9=0856|35=X|49=LFX|56=MKT.UAT.QPU600|34=115|52=20190307-15:21:05.449|262=MDReqID_1|55=GBP/USD|64=20190311|268=7|279=1|269=0|278=b-47005859259503187-3|280=7COBA0B1|270=1.30998|272=20190307|273=15:21:05.318|9122=15:21:05.310|290=2|279=1|269=0|278=b-47005859259503187-5|280=7COBA0B2|270=1.30997|272=20190307|273=15:21:05.318|9122=15:21:05.310|290=4|279=1|269=0|278=b-47005859259503187-8|280=7COBA0B3|270=1.30996|272=20190307|273=15:21:05.318|9122=15:21:05.310|290=7|279=1|269=1|278=o-47005859259503187-5|280=7COBA0O1|270=1.31021|272=20190307|273=15:21:05.318|9122=15:21:05.310|290=4|279=1|269=1|278=o-47005859259503187-9|280=7COBA0O2|270=1.31023|272=20190307|273=15:21:05.318|9122=15:21:05.310|290=8|279=0|269=1|278=o-47005859259503187-10|280=543|270=1.31023|271=4000000|272=20190307|273=15:21:05.415|9122=15:21:01.040|276=A|282=QPU90|290=9|279=2|269=1|280=7COBA0O3|10=113|
8=FIX.4.4|9=0365|35=X|49=LFX|56=MKT.UAT.QPU600|34=116|52=20190307-15:21:05.648|262=MDReqID_1|55=GBP/USD|64=20190311|268=2|279=1|269=0|278=b-47005859458077002-2|280=1GBP/USD.1M@BAR.7.RFQ|270=1.31001|272=20190307|273=15:21:05.508|9122=15:21:05.087|290=1|279=1|269=0|278=b-47005859458077002-4|280=1GBP/USD.5M@BAR.7.RFQ|270=1.30999|272=20190307|273=15:21:05.508|9122=15:21:05.088|290=3|10=052|
8=FIX.4.4|9=0574|35=X|49=LFX|56=MKT.UAT.QPU600|34=117|52=20190307-15:21:05.848|262=MDReqID_1|55=GBP/USD|64=20190311|268=4|279=1|269=0|278=b-47005859658299672-8|280=7COBA0B2|270=1.30996|272=20190307|273=15:21:05.714|9122=15:21:05.714|290=7|279=1|269=0|278=b-47005859658299672-9|280=7COBA0B3|270=1.30995|272=20190307|273=15:21:05.714|9122=15:21:05.714|290=8|279=1|269=1|278=o-47005859658299672-7|280=7COBA0O1|270=1.31022|272=20190307|273=15:21:05.714|9122=15:21:05.714|290=6|279=1|269=1|278=o-47005859658299672-10|280=7COBA0O2|270=1.31024|272=20190307|273=15:21:05.714|9122=15:21:05.714|290=9|10=097|
8=FIX.4.4|9=0335|35=X|49=LFX|56=MKT.UAT.QPU600|34=118|52=20190307-15:21:06.048|262=MDReqID_1|55=GBP/USD|64=20190311|268=2|279=1|269=0|278=b-47005859858430537-8|280=9MS0b1|270=1.30996|272=20190307|273=15:21:05.969|9122=15:21:05.968|290=7|279=1|269=1|278=o-47005859858430537-8|280=9MS0a1|270=1.31022|272=20190307|273=15:21:05.969|9122=15:21:05.968|290=7|10=248|
8=FIX.4.4|9=0365|35=X|49=LFX|56=MKT.UAT.QPU600|34=119|52=20190307-15:21:06.448|262=MDReqID_1|55=GBP/USD|64=20190311|268=2|279=1|269=0|278=b-47005860258471423-7|280=1GBP/USD.1M@BAR.7.RFQ|270=1.30996|272=20190307|273=15:21:06.403|9122=15:21:06.078|290=6|279=1|269=0|278=b-47005860258471423-9|280=1GBP/USD.5M@BAR.7.RFQ|270=1.30994|272=20190307|273=15:21:06.403|9122=15:21:06.079|290=8|10=073|
8=FIX.4.4|9=0457|35=X|49=LFX|56=MKT.UAT.QPU600|34=120|52=20190307-15:21:06.849|262=MDReqID_1|55=GBP/USD|64=20190311|268=3|279=1|269=0|278=b-47005860658701694-3|280=7COBA0B1|270=1.30997|272=20190307|273=15:21:06.716|9122=15:21:06.716|290=2|279=1|269=1|278=o-47005860658701694-6|280=7COBA0O1|270=1.31021|272=20190307|273=15:21:06.717|9122=15:21:06.716|290=5|279=1|269=1|278=o-47005860658701694-10|280=7COBA0O2|270=1.31023|272=20190307|273=15:21:06.717|9122=15:21:06.716|290=9|10=107|
8=FIX.4.4|9=0456|35=X|49=LFX|56=MKT.UAT.QPU600|34=121|52=20190307-15:21:07.849|262=MDReqID_1|55=GBP/USD|64=20190311|268=3|279=1|269=0|278=b-47005861658974024-7|280=7COBA0B2|270=1.30995|272=20190307|273=15:21:07.719|9122=15:21:07.718|290=6|279=1|269=0|278=b-47005861658974024-9|280=7COBA0B3|270=1.30994|272=20190307|273=15:21:07.719|9122=15:21:07.718|290=8|279=1|269=1|278=o-47005861658974024-9|280=7COBA0O2|270=1.31022|272=20190307|273=15:21:07.719|9122=15:21:07.718|290=8|10=091|
8=FIX.4.4|9=0441|35=X|49=LFX|56=MKT.UAT.QPU600|34=122|52=20190307-15:21:08.649|262=MDReqID_1|55=GBP/USD|64=20190311|268=4|279=0|269=0|278=b-47005862459127127-10|280=5182|270=1.30994|271=4000000|272=20190307|273=15:21:08.520|9122=15:21:08.485|276=A|282=QPU90|290=9|279=2|269=0|280=5256|279=0|269=1|278=o-47005862459127127-10|280=7COBA0O3|270=1.31023|271=5000000|15=GBP|272=20190307|273=15:21:07.719|9122=15:21:07.718|276=A|282=QPU17|290=9|279=2|269=1|280=543|10=153|
8=FIX.4.4|9=0622|35=X|49=LFX|56=MKT.UAT.QPU600|34=123|52=20190307-15:21:08.849|262=MDReqID_1|55=GBP/USD|64=20190311|268=5|279=1|269=0|278=b-47005862659254220-7|280=7COBA0B2|270=1.30996|272=20190307|273=15:21:08.728|9122=15:21:08.726|290=6|279=1|269=0|278=b-47005862659254220-8|280=7COBA0B3|270=1.30995|272=20190307|273=15:21:08.728|9122=15:21:08.726|290=7|279=0|269=1|278=o-47005862659254220-9|280=543|270=1.31023|271=4000000|272=20190307|273=15:21:08.520|9122=15:21:01.040|276=A|282=QPU90|290=8|279=1|269=1|278=o-47005862659254220-10|280=7COBA0O2|270=1.31023|272=20190307|273=15:21:08.728|9122=15:21:08.726|290=9|279=2|269=1|280=7COBA0O3|10=047|
8=FIX.4.4|9=0574|35=X|49=LFX|56=MKT.UAT.QPU600|34=124|52=20190307-15:21:09.049|262=MDReqID_1|55=GBP/USD|64=20190311|268=4|279=1|269=0|278=b-47005862859231880-3|280=7COBA0B1|270=1.30998|272=20190307|273=15:21:09.048|9122=15:21:09.046|290=2|279=1|269=0|278=b-47005862859231880-8|280=7COBA0B3|270=1.30996|272=20190307|273=15:21:09.048|9122=15:21:09.046|290=7|279=1|269=1|278=o-47005862859231880-8|280=7COBA0O1|270=1.31022|272=20190307|273=15:21:09.048|9122=15:21:09.046|290=7|279=1|269=1|278=o-47005862859231880-10|280=7COBA0O2|270=1.31024|272=20190307|273=15:21:09.048|9122=15:21:09.046|290=9|10=044|
8=FIX.4.4|9=0365|35=X|49=LFX|56=MKT.UAT.QPU600|34=125|52=20190307-15:21:09.249|262=MDReqID_1|55=GBP/USD|64=20190311|268=2|279=1|269=0|278=b-47005863059267491-2|280=1GBP/USD.1M@BAR.7.RFQ|270=1.31001|272=20190307|273=15:21:09.226|9122=15:21:09.088|290=1|279=1|269=0|278=b-47005863059267491-4|280=1GBP/USD.5M@BAR.7.RFQ|270=1.30999|272=20190307|273=15:21:09.226|9122=15:21:09.088|290=3|10=074|
8=FIX.4.4|9=0396|35=X|49=LFX|56=MKT.UAT.QPU600|34=126|52=20190307-15:21:09.650|262=MDReqID_1|55=GBP/USD|64=20190311|268=3|279=1|269=0|278=b-47005863459708165-6|280=9MS0b1|270=1.30998|272=20190307|273=15:21:09.515|9122=15:21:09.512|290=5|279=0|269=1|278=o-47005863459708165-10|280=7COBA0O3|270=1.31024|271=5000000|15=GBP|272=20190307|273=15:21:09.048|9122=15:21:09.046|276=A|282=QPU17|290=9|279=2|269=1|280=9MS0a1|10=248|
8=FIX.4.4|9=0628|35=X|49=LFX|56=MKT.UAT.QPU600|34=127|52=20190307-15:21:10.250|262=MDReqID_1|55=GBP/USD|64=20190311|268=5|279=1|269=0|278=b-47005864059688291-4|280=7COBA0B1|270=1.31|272=20190307|273=15:21:10.197|9122=15:21:10.196|290=3|279=1|269=0|278=b-47005864059688291-7|280=7COBA0B2|270=1.30998|272=20190307|273=15:21:10.197|9122=15:21:10.196|290=6|279=1|269=0|278=b-47005864059688291-8|280=7COBA0B3|270=1.30997|272=20190307|273=15:21:10.197|9122=15:21:10.196|290=7|279=0|269=1|278=o-47005864059688291-9|280=9MS0a1|270=1.31024|271=1000000|15=GBP|272=20190307|273=15:21:09.515|9122=15:21:09.512|276=A|282=QPU47|290=8|279=2|269=1|280=7COBA0O3|10=230|
8=FIX.4.4|9=0399|35=X|49=LFX|56=MKT.UAT.QPU600|34=128|52=20190307-15:21:11.250|262=MDReqID_1|55=GBP/USD|64=20190311|268=3|279=1|269=1|278=o-47005865059950760-8|280=7COBA0O1|270=1.31023|272=20190307|273=15:21:11.170|9122=15:21:11.169|290=7|279=0|269=1|278=o-47005865059950760-10|280=2BNP53|270=1.31025|271=10000000|15=GBP|272=20190307|273=15:20:34.935|9122=15:20:34.901|276=A|282=QPU08|290=9|279=2|269=1|280=7COBA0O2|10=077|
8=FIX.4.4|9=0431|35=X|49=LFX|56=MKT.UAT.QPU600|34=129|52=20190307-15:21:11.850|262=MDReqID_1|55=GBP/USD|64=20190311|268=4|279=0|269=0|278=b-47005865660392456-6|280=5256|270=1.30999|271=4000000|272=20190307|273=15:21:11.810|9122=15:21:11.775|276=A|282=QPU90|290=5|279=0|269=0|278=b-47005865660392456-9|280=5126|270=1.30998|271=4000000|272=20190307|273=15:21:11.810|9122=15:21:11.775|276=A|282=QPU90|290=8|279=2|269=0|280=2BNP53|279=2|269=0|280=5182|10=107|
8=FIX.4.4|9=0340|35=X|49=LFX|56=MKT.UAT.QPU600|34=130|52=20190307-15:21:12.250|262=MDReqID_1|55=GBP/USD|64=20190311|268=2|279=1|269=0|278=b-47005866060321205-10|280=7COBA0B3|270=1.30998|272=20190307|273=15:21:12.171|9122=15:21:12.171|290=9|279=1|269=1|278=o-47005866060321205-9|280=7COBA0O1|270=1.31024|272=20190307|273=15:21:12.171|9122=15:21:12.171|290=8|10=087|
8=FIX.4.4|9=0365|35=X|49=LFX|56=MKT.UAT.QPU600|34=131|52=20190307-15:21:12.450|262=MDReqID_1|55=GBP/USD|64=20190311|268=2|279=1|269=0|278=b-47005866260349503-1|280=1GBP/USD.1M@BAR.7.RFQ|270=1.31005|272=20190307|273=15:21:12.332|9122=15:21:12.093|290=0|279=1|269=0|278=b-47005866260349503-3|280=1GBP/USD.5M@BAR.7.RFQ|270=1.31003|272=20190307|273=15:21:12.332|9122=15:21:12.094|290=2|10=241|
8=FIX.4.4|9=0336|35=X|49=LFX|56=MKT.UAT.QPU600|34=132|52=20190307-15:21:13.251|262=MDReqID_1|55=GBP/USD|64=20190311|268=2|279=1|269=0|278=b-47005867060801857-7|280=9MS0b1|270=1.30999|272=20190307|273=15:21:13.175|9122=15:21:13.174|290=6|279=1|269=1|278=o-47005867060801857-10|280=9MS0a1|270=1.31025|272=20190307|273=15:21:13.175|9122=15:21:13.174|290=9|10=220|
8=FIX.4.4|9=0340|35=X|49=LFX|56=MKT.UAT.QPU600|34=133|52=20190307-15:21:14.851|262=MDReqID_1|55=GBP/USD|64=20190311|268=2|279=1|269=0|278=b-47005868661317687-8|280=7COBA0B2|270=1.30999|272=20190307|273=15:21:14.687|9122=15:21:14.686|290=7|279=1|269=1|278=o-47005868661317687-10|280=7COBA0O1|270=1.31025|272=20190307|273=15:21:14.687|9122=15:21:14.686|290=9|10=208|
8=FIX.4.4|9=0222|35=X|49=LFX|56=MKT.UAT.QPU600|34=134|52=20190307-15:21:15.852|262=MDReqID_1|55=GBP/USD|64=20190311|268=1|279=1|269=1|278=o-47005869661647798-8|280=7COBA0O1|270=1.31024|272=20190307|273=15:21:15.689|9122=15:21:15.688|290=7|10=229|
8=FIX.4.4|9=0365|35=X|49=LFX|56=MKT.UAT.QPU600|34=135|52=20190307-15:21:17.252|262=MDReqID_1|55=GBP/USD|64=20190311|268=2|279=1|269=0|278=b-47005871062033338-2|280=1GBP/USD.1M@BAR.7.RFQ|270=1.31001|272=20190307|273=15:21:17.107|9122=15:21:17.084|290=1|279=1|269=0|278=b-47005871062033338-8|280=1GBP/USD.5M@BAR.7.RFQ|270=1.30999|272=20190307|273=15:21:17.108|9122=15:21:17.084|290=7|10=029|
8=FIX.4.4|9=0440|35=X|49=LFX|56=MKT.UAT.QPU600|34=136|52=20190307-15:21:17.252|262=MDReqID_1|55=GBP/USD|64=20190311|268=4|279=0|269=0|278=b-47005871062127981-9|280=2BNP53|270=1.30996|271=10000000|15=GBP|272=20190307|273=15:20:34.935|9122=15:20:34.901|276=A|282=QPU08|290=8|279=0|269=0|278=b-47005871062127981-10|280=5199|270=1.30994|271=4000000|272=20190307|273=15:21:17.055|9122=15:21:17.020|276=A|282=QPU90|290=9|279=2|269=0|280=5256|279=2|269=0|280=5126|10=055|
8=FIX.4.4|9=0573|35=X|49=LFX|56=MKT.UAT.QPU600|34=137|52=20190307-15:21:19.252|262=MDReqID_1|55=GBP/USD|64=20190311|268=4|279=1|269=0|278=b-47005873062523887-6|280=7COBA0B1|270=1.30999|272=20190307|273=15:21:19.149|9122=15:21:19.148|290=5|279=1|269=0|278=b-47005873062523887-7|280=7COBA0B2|270=1.30998|272=20190307|273=15:21:19.149|9122=15:21:19.148|290=6|279=1|269=0|278=b-47005873062523887-8|280=7COBA0B3|270=1.30997|272=20190307|273=15:21:19.149|9122=15:21:19.148|290=7|279=1|269=1|278=o-47005873062523887-8|280=7COBA0O1|270=1.31023|272=20190307|273=15:21:19.149|9122=15:21:19.148|290=7|10=024|
8=FIX.4.4|9=0430|35=X|49=LFX|56=MKT.UAT.QPU600|34=138|52=20190307-15:21:19.653|262=MDReqID_1|55=GBP/USD|64=20190311|268=4|279=0|269=0|278=b-47005873462697282-7|280=544|270=1.30999|271=4000000|272=20190307|273=15:21:19.475|9122=15:21:19.440|276=A|282=QPU90|290=6|279=0|269=0|278=b-47005873462697282-9|280=5253|270=1.30998|271=4000000|272=20190307|273=15:21:19.475|9122=15:21:19.440|276=A|282=QPU90|290=8|279=2|269=0|280=5199|279=2|269=0|280=2BNP53|10=105|
